Workbook

Sheet README
A1: Seasonal Agriculture Performance Analysis
A2: VOIS AICTE Batch1 2026-2027 — Major Project (Excel phase)
A4: Dataset: seasonal_agriculture_performance_dataset.csv — 4,000 farm records | 8 states | 8 crops | 3 seasons (Kharif, Rabi, Zaid)
A6: How this workbook is organised
A7: Sheet | B7: What's in it
A8: Raw_Data | B8: The original dataset, unedited (4,000 rows).
A9: Cleaning_Reference | B9: Per-crop yield quartiles used for imputing/capping outliers.
A10: Cleaned_Data | B10: Live formulas: missing values imputed, outliers capped, with flag columns showing what was changed.
A11: Data_Dictionary | B11: Column definitions and a plain-English summary of the cleaning steps.
A12: Season_Summary | B12: The core pivot-style table — ~23 metrics compared across Kharif / Rabi / Zaid.
A13: Season_Crop_Matrix | B13: Average yield and profit for each crop, broken down by season.
A14: Season_State_Matrix | B14: Average yield for each state, broken down by season (regional consistency check).
A15: Irrigation_Analysis | B15: Farm counts and water efficiency by irrigation method and season.
A16: Correlation_Analysis | B16: Pearson correlation coefficients between key variables and yield/profit.
A17: Charts | B17: Visualisations of the above (bar, pie, scatter) — all linked live to the data.
A18: Key_Insights_Recommendations | B18: Written findings mapped to the project's key questions, plus recommendations.
A20: Method note
A21: All summary/matrix/correlation figures are Excel formulas (AVERAGEIFS, SUMIFS, COUNTIFS, CORREL, INDEX/MATCH) referencing Cleaned_Data — nothing is hardcoded, so the workbook recalculates if the raw data changes. The next phase of this project (Python / Jupyter Notebook) will go deeper: statistical tests, per-season correlation, regression and richer visualisation.

Sheet Data_Dictionary
A1: Data Dictionary
A2: Field descriptions for the Seasonal Agriculture Performance dataset (4,000 farm records, 8 states, 8 crops, 3 seasons).
A4: Column | B4: Description
A5: Farm_ID | B5: Unique identifier for each farm record
A6: State | B6: Indian state where the farm is located (8 states)
A7: District | B7: District within the state
A8: Crop | B8: Crop cultivated (8 crop types)
A9: Season | B9: Cropping season: Kharif (monsoon), Rabi (winter), Zaid (summer)
A10: Farm_Area_Hectares | B10: Total cultivated area of the farm, in hectares
A11: Rainfall_mm | B11: Total rainfall received during the season, in millimetres
A12: Avg_Temperature_C | B12: Average temperature during the season, in Celsius
A13: Humidity_pct | B13: Average relative humidity, in percent
A14: Sunlight_Hours_Day | B14: Average sunlight hours per day
A15: Soil_pH | B15: Soil pH level (acidity/alkalinity)
... A32: Disease_Pest_Risk_pct | B32: Estimated disease/pest risk score, percent
A35: Cleaning Methodology (see Cleaned_Data sheet)
A36: 1. Missing Rainfall_mm (48 records) imputed with the season average.
A37: 2. Missing Soil_Moisture_pct (40 records) imputed with the season average.
A38: 3. Missing Yield_Tonnes_Ha (32 records) imputed with the Season x Crop average.
A39: 4. Yield outliers capped at the crop's IQR upper bound (Q3 + 1.5xIQR); see Cleaning_Reference sheet.
A40: 5. Production_Recalculated_t recomputes production from the cleaned yield x farm area for consistency.
A41: 6. No duplicate Farm_ID values were found in the raw dataset.

Sheet Raw_Data
A1: Farm_ID | B1: State | C1: District | D1: Crop | E1: Season | F1: Farm_Area_Hectares | G1: Rainfall_mm | H1: Avg_Temperature_C | I1: Humidity_pct | J1: Sunlight_Hours_Day | K1: Soil_pH | L1: Soil_Moisture_pct | M1: Nitrogen_kg_ha | N1: Phosphorus_kg_ha | O1: Potassium_kg_ha | P1: Irrigation_Method | Q1: Fertilizer_kg_ha | R1: Pesticide_Litre_ha | S1: Seed_Quality_Score | T1: Yield_Tonnes_Ha | U1: Production_Tonnes | V1: Market_Price_INR_Tonne | W1: Total_Cost_INR | X1: Revenue_INR | Y1: Profit_INR | Z1: Water_Used_m3 | AA1: Water_Efficiency_t_per_1000m3 | AB1: Disease_Pest_Risk_pct
A2: SF10001 | B2: Andhra Pradesh | C2: Rajkot | D2: Wheat | E2: Kharif | F2: 0.53 | G2: 486.4 | H2: 24.3 | I2: 69.1 | J2: 5.8 | K2: 7.14 | L2: 32.8 | M2: 75.8 | N2: 61.3 | O2: 91 | P2: Drip | Q2: 242.7 | R2: 4.33 | S2: 0.76 | T2: 2.46 | U2: 1.3 | V2: 23700 | W2: 42662 | X2: 30810 | Y2: -11852 | Z2: 237 | AA2: 5.485 | AB2: 55.3
A3: SF10002 | B3: Maharashtra | C3: Nalgonda | D3: Maize | E3: Kharif | F3: 6.53 | G3: 855.4 | H3: 25.7 | I3: 78.4 | J3: 5.1 | K3: 5.2 | L3: 32 | M3: 82.1 | N3: 35.4 | O3: 121.8 | P3: Flood | Q3: 271.4 | R3: 6.86 | S3: 0.94 | T3: 0.3 | U3: 1.96 | V3: 20613 | W3: 492351 | X3: 40401 | Y3: -451950 | Z3: 4953 | AA3: 0.396 | AB3: 49.9
A4: SF10003 | B4: Telangana | C4: Warangal | D4: Pulses | E4: Rabi | F4: 4.86 | G4: 455.6 | H4: 23.9 | I4: 56.4 | J4: 10.3 | K4: 5.82 | L4: 8.1 | M4: 118.5 | N4: 51.5 | O4: 117.9 | P4: Drip | Q4: 162.6 | R4: 6.08 | S4: 0.98 | T4: 0.52 | U4: 2.53 | V4: 75283 | W4: 315210 | X4: 190466 | Y4: -124744 | Z4: 1275 | AA4: 1.984 | AB4: 33.7
A5: SF10004 | B5: Telangana | C5: Indore | D5: Rice | E5: Kharif | F5: 4.5 | G5: 753.2 | H5: 29.7 | I5: 65.2 | J5: 6.3 | K5: 5.98 | L5: 23.7 | M5: 138.6 | N5: 55.6 | O5: 115.5 | P5: Rainfed | Q5: 182.2 | R5: 6.39 | S5: 0.74 | T5: 1.84 | U5: 8.28 | V5: 24244 | W5: 296444 | X5: 200740 | Y5: -95704 | Z5: 3834 | AA5: 2.16 | AB5: 50.6
A6: SF10005 | B6: Karnataka | C6: Ludhiana | D6: Maize | E6: Zaid | F6: 4.21 | G6: 101.6 | H6: 34.1 | I6: 55.2 | J6: 6.5 | K6: 6.9 | L6: 29.3 | M6: 124.1 | N6: 69 | O6: 121.4 | P6: Flood | Q6: 244.9 | R6: 7.61 | S6: 0.9 | T6: 2.21 | U6: 9.3 | V6: 20818 | W6: 337959 | X6: 193607 | Y6: -144352 | Z6: 3287 | AA6: 2.829 | AB6: 32.3
A7: SF10006 | B7: Gujarat | C7: Raichur | D7: Pulses | E7: Zaid | F7: 5.46 | G7: 356 | H7: 33.6 | I7: 49 | J7: 8.3 | K7: 6.93 | L7: 11.4 | M7: 105.1 | N7: 34.7 | O7: 78.7 | P7: Rainfed | Q7: 58.8 | R7: 4.48 | S7: 0.89 | T7: 0.72 | U7: 3.93 | V7: 68593 | W7: 302333 | X7: 269570 | Y7: -32763 | Z7: 1093 | AA7: 3.596 | AB7: 57.1
A8: SF10007 | B8: Telangana | C8: Warangal | D8: Wheat | E8: Rabi | F8: 8.13 | G8: 432.2 | H8: 23.5 | I8: 50.8 | J8: 9.5 | K8: 6.96 | L8: 24.7 | M8: 115.8 | N8: 69.4 | O8: 109.8 | P8: Rainfed | Q8: 181.6 | R8: 7.99 | S8: 0.87 | T8: 2.53 | U8: 20.57 | V8: 22951 | W8: 513341 | X8: 472102 | Y8: -41239 | Z8: 2368 | AA8: 8.687 | AB8: 31.6
A9: SF10008 | B9: Tamil Nadu | C9: Ludhiana | D9: Pulses | E9: Kharif | F9: 5.34 | G9: 860.2 | H9: 29 | I9: 64.9 | J9: 7.9 | K9: 6.09 | L9: 36.9 | M9: 112.7 | N9: 60.9 | O9: 115.9 | P9: Sprinkler | Q9: 245.8 | R9: 5.89 | S9: 0.7 | T9: 1.18 | U9: 6.3 | V9: 70042 | W9: 436200 | X9: 441265 | Y9: 5065 | Z9: 1704 | AA9: 3.697 | AB9: 54.2
A10: SF10009 | B10: Karnataka | C10: Guntur | D10: Cotton | E10: Zaid | F10: 6.98 | G10: 624.7 | H10: 33.4 | I10: 46.8 | J10: 7.9 | K10: 6.41 | L10: 12.3 | M10: 66.9 | N10: 47.6 | O10: 134.2 | P10: Sprinkler | Q10: 190.7 | R10: 2.21 | S10: 0.88 | T10: 1.53 | U10: 10.68 | V10: 70771 | W10: 525129 | X10: 755834 | Y10: 230705 | Z10: 5079 | AA10: 2.103 | AB10: 54.7
A11: SF10010 | B11: Tamil Nadu | C11: Raichur | D11: Chilli | E11: Rabi | F11: 13.69 | G11: 415.8 | H11: 22.3 | I11: 57.3 | J11: 8.6 | K11: 6.6 | L11: 23.3 | M11: 117.9 | N11: 37.2 | O11: 116.6 | P11: Drip | Q11: 168.8 | R11: 7.29 | S11: 0.7 | T11: 2.29 | U11: 31.35 | V11: 94383 | W11: 1004072 | X11: 2958907 | Y11: 1954835 | Z11: 5984 | AA11: 5.239 | AB11: 41.7
A12: SF10011 | B12: Maharashtra | C12: Krishna | D12: Wheat | E12: Rabi | F12: 4.7 | G12: 390.8 | H12: 24.5 | I12: 43.5 | J12: 7.8 | K12: 5.93 | L12: 25.2 | M12: 137.9 | N12: 31.4 | O12: 70 | P12: Sprinkler | Q12: 224.4 | R12: 5.9 | S12: 0.89 | T12: 1.44 | U12: 6.77 | V12: 20806 | W12: 289759 | X12: 140857 | Y12: -148902 | Z12: 2371 | AA12: 2.855 | AB12: 33.5
A13: SF10012 | B13: Telangana | C13: Rajkot | D13: Maize | E13: Rabi | F13: 14.07 | G13: 315.3 | H13: 24.2 | I13: 53.7 | J13: 5.9 | K13: 5.87 | L13: 29.4 | M13: 100.6 | N13: 50.8 | O13: 65.8 | P13: Drip | Q13: 178.7 | R13: 5.34 | S13: 0.71 | T13: 1.36 | U13: 19.14 | V13: 20120 | W13: 964512 | X13: 385097 | Y13: -579415 | Z13: 7467 | AA13: 2.563 | AB13: 35
... A29: SF10028 | B29: Punjab | C29: Rajkot | D29: Rice | E29: Rabi | F29: 10.47 | G29: 93.9 | H29: 27.3 | I29: 45.4 | J29: 7.7 | K29: 6.89 | L29: 27 | M29: 115.6 | N29: 64.9 | O29: 123.2 | P29: Rainfed | Q29: 210.2 | R29: 2.42 | S29: 0.74 | T29: 2.45 | U29: 25.65 | V29: 21364 | W29: 545453 | X29: 547987 | Y29: 2534 | Z29: 9077 | AA29: 2.826 | AB29: 45.7
A30: SF10029 | B30: Tamil Nadu | C30: Rajkot | D30: Maize | E30: Rabi | F30: 12.94 | G30: 443.1 | H30: 23 | I30: 45.7 | J30: 6.3 | K30: 6.32 | M30: 139.3 | N30: 51.3 | O30: 92.5 | P30: Sprinkler | Q30: 286.7 | R30: 8.22 | S30: 0.97 | T30: 3.01 | U30: 38.95 | V30: 20272 | W30: 1176978 | X30: 789594 | Y30: -387384 | Z30: 8230 | AA30: 4.733 | AB30: 32.1
A31: SF10030 | B31: Tamil Nadu | C31: Rajkot | D31: Groundnut | E31: Zaid | F31: 13.15 | G31: 565.4 | H31: 32.7 | I31: 50.7 | J31: 7.3 | K31: 6.65 | L31: 15.6 | M31: 158 | N31: 46.8 | O31: 151 | P31: Sprinkler | Q31: 147.4 | R31: 5.5 | S31: 0.89 | T31: 1.94 | U31: 25.51 | V31: 49492 | W31: 695563 | X31: 1262541 | Y31: 566978 | Z31: 7423 | AA31: 3.437 | AB31: 30.6
A32: SF10031 | B32: Telangana | C32: Nalgonda | D32: Chilli | E32: Rabi | F32: 11.96 | G32: 284.2 | H32: 24.1 | I32: 62.1 | J32: 7 | K32: 6.93 | L32: 31.7 | M32: 188.8 | N32: 47.8 | O32: 101.6 | P32: Rainfed | Q32: 250.8 | R32: 4.06 | S32: 0.66 | T32: 1.51 | U32: 18.06 | V32: 102219 | W32: 738746 | X32: 1846075 | Y32: 1107329 | Z32: 4721 | AA32: 3.825 | AB32: 40.2
A33: SF10032 | B33: Madhya Pradesh | C33: Krishna | D33: Groundnut | E33: Zaid | F33: 0.69 | G33: 372.1 | H33: 31.7 | I33: 30.8 | J33: 7.4 | K33: 7.92 | L33: 12.2 | M33: 127.3 | N33: 66.2 | O33: 131.1 | P33: Drip | Q33: 139.4 | R33: 4.39 | S33: 0.96 | T33: 0.3 | U33: 0.21 | V33: 54155 | W33: 43431 | X33: 11373 | Y33: -32058 | Z33: 259 | AA33: 0.811 | AB33: 37.4
A34: SF10033 | B34: Madhya Pradesh | C34: Indore | D34: Cotton | E34: Kharif | F34: 11.35 | G34: 1066.8 | H34: 30.3 | I34: 76.6 | J34: 6.4 | K34: 7.56 | L34: 35.9 | M34: 104.2 | N34: 49.9 | O34: 106.8 | P34: Sprinkler | Q34: 230.7 | R34: 4.16 | S34: 0.7 | T34: 0.64 | U34: 7.26 | V34: 72112 | W34: 782371 | X34: 523533 | Y34: -258838 | Z34: 9585 | AA34: 0.757 | AB34: 67.7
A35: SF10034 | B35: Andhra Pradesh | C35: Guntur | D35: Maize | E35: Kharif | F35: 9.8 | G35: 849 | H35: 26.4 | I35: 88 | J35: 8.2 | K35: 6.03 | L35: 35.5 | M35: 154.3 | N35: 49.1 | O35: 129.8 | P35: Sprinkler | Q35: 220.2 | R35: 4.34 | S35: 0.72 | T35: 3.65 | U35: 35.77 | V35: 21914 | W35: 782502 | X35: 783864 | Y35: 1362 | Z35: 5884 | AA35: 6.079 | AB35: 52.1
A36: SF10035 | B36: Madhya Pradesh | C36: Ludhiana | D36: Wheat | E36: Rabi | F36: 11.57 | G36: 427.5 | H36: 24 | I36: 59.3 | J36: 6.7 | K36: 6.71 | L36: 28.5 | M36: 157.3 | N36: 71.5 | O36: 84.3 | P36: Sprinkler | Q36: 186.8 | R36: 1.13 | S36: 0.86 | T36: 3.83 | U36: 44.31 | V36: 26126 | W36: 648827 | X36: 1157643 | Y36: 508816 | Z36: 5400 | AA36: 8.206 | AB36: 61.4
A37: SF10036 | B37: Madhya Pradesh | C37: Indore | D37: Cotton | E37: Zaid | F37: 7.05 | G37: 179.4 | H37: 34.1 | I37: 55.5 | J37: 8.7 | K37: 7 | L37: 14.8 | M37: 94.3 | N37: 66.8 | O37: 101.3 | P37: Flood | Q37: 231.5 | R37: 7.26 | S37: 0.96 | T37: 0.75 | U37: 5.29 | V37: 66996 | W37: 511293 | X37: 354409 | Y37: -156884 | Z37: 5944 | AA37: 0.89 | AB37: 29
A38: SF10037 | B38: Tamil Nadu | C38: Nalgonda | D38: Cotton | E38: Rabi | F38: 3.11 | G38: 429.3 | H38: 23.6 | I38: 60.1 | J38: 7.9 | K38: 6.96 | L38: 20.7 | M38: 40 | N38: 73.9 | O38: 114.2 | P38: Drip | Q38: 229 | R38: 6.96 | S38: 0.68 | T38: 1.71 | U38: 5.32 | V38: 52396 | W38: 243775 | X38: 278747 | Y38: 34972 | Z38: 1780 | AA38: 2.989 | AB38: 33
A39: SF10038 | B39: Andhra Pradesh | C39: Ludhiana | D39: Cotton | E39: Kharif | F39: 2.79 | G39: 820.1 | H39: 26.3 | I39: 74.6 | J39: 7.5 | K39: 7.62 | L39: 31.9 | M39: 123.2 | N39: 91.7 | O39: 80.6 | P39: Flood | Q39: 153.2 | R39: 5.91 | S39: 0.68 | T39: 0.7 | U39: 1.95 | V39: 66405 | W39: 175756 | X39: 129490 | Y39: -46266 | Z39: 3058 | AA39: 0.638 | AB39: 52.5
A40: SF10039 | B40: Telangana | C40: Warangal | D40: Wheat | E40: Kharif | F40: 4.69 | G40: 657.7 | H40: 27.1 | I40: 64.9 | J40: 6.2 | K40: 7.85 | L40: 31.9 | M40: 87.6 | N40: 87.5 | O40: 81.5 | P40: Drip | Q40: 218.9 | R40: 4.78 | S40: 0.92 | T40: 0.98 | U40: 4.6 | V40: 25408 | W40: 293568 | X40: 116877 | Y40: -176691 | Z40: 2392 | AA40: 1.923 | AB40: 50
A41: SF10040 | B41: Tamil Nadu | C41: Ludhiana | D41: Maize | E41: Kharif | F41: 6.12 | G41: 936 | H41: 31.8 | I41: 56.3 | J41: 7.1 | K41: 7.03 | L41: 30.3 | M41: 91.9 | N41: 48 | O41: 103.6 | P41: Rainfed | Q41: 46.3 | R41: 8.07 | S41: 0.79 | T41: 3.24 | U41: 19.83 | V41: 24731 | W41: 321710 | X41: 490416 | Y41: 168706 | Z41: 2144 | AA41: 9.249 | AB41: 46.7
A42: SF10041 | B42: Karnataka | C42: Indore | D42: Pulses | E42: Kharif | F42: 12.31 | G42: 768.4 | H42: 29 | I42: 67 | J42: 6.1 | K42: 8.22 | L42: 26.7 | M42: 69.5 | N42: 49.1 | O42: 98.6 | P42: Flood | Q42: 214.2 | R42: 7.11 | S42: 0.73 | T42: 0.3 | U42: 3.69 | V42: 95238 | W42: 791517 | X42: 351428 | Y42: -440089 | Z42: 6153 | AA42: 0.6 | AB42: 54.7
... A44: SF10043 | B44: Karnataka | C44: Krishna | D44: Rice | E44: Kharif | F44: 9.47 | G44: 639.2 | H44: 22.6 | I44: 74.9 | J44: 4.9 | K44: 5.73 | L44: 43.6 | M44: 66.1 | N44: 54.9 | O44: 125.5 | P44: Rainfed | Q44: 313.4 | R44: 4.78 | S44: 0.94 | T44: 0.9 | U44: 8.52 | V44: 25346 | W44: 744619 | X44: 215948 | Y44: -528671 | Z44: 7926 | AA44: 1.075 | AB44: 52
A45: SF10044 | B45: Tamil Nadu | C45: Erode | D45: Wheat | E45: Rabi | F45: 7.56 | G45: 460.1 | H45: 24 | I45: 58.7 | J45: 6.7 | K45: 6.6 | M45: 96.2 | N45: 42.9 | O45: 139.3 | P45: Sprinkler | Q45: 241.9 | R45: 5.34 | S45: 0.69 | T45: 2.6 | U45: 19.66 | V45: 24887 | W45: 550176 | X45: 489278 | Y45: -60898 | Z45: 4545 | AA45: 4.326 | AB45: 44.7
A46: SF10045 | B46: Madhya Pradesh | C46: Krishna | D46: Wheat | E46: Kharif | F46: 14.23 | G46: 853.7 | H46: 28.2 | I46: 77.6 | J46: 6.9 | K46: 7.04 | L46: 31.8 | M46: 109.5 | N46: 61.7 | O46: 148.7 | P46: Drip | Q46: 163.7 | R46: 4.26 | S46: 0.85 | T46: 3.35 | U46: 47.67 | V46: 23547 | W46: 980255 | X46: 1122485 | Y46: 142230 | Z46: 5966 | AA46: 7.99 | AB46: 55.4
A47: SF10046 | B47: Telangana | C47: Erode | D47: Wheat | E47: Kharif | F47: 2.14 | G47: 485.7 | H47: 28 | I47: 80.1 | J47: 7.2 | K47: 8.08 | L47: 34.7 | M47: 111 | N47: 56.6 | O47: 74.9 | P47: Drip | Q47: 146.2 | R47: 4.25 | S47: 0.95 | T47: 0.32 | U47: 0.68 | V47: 25224 | W47: 116463 | X47: 17152 | Y47: -99311 | Z47: 791 | AA47: 0.86 | AB47: 49.4
A48: SF10047 | B48: Andhra Pradesh | C48: Nalgonda | D48: Groundnut | E48: Kharif | F48: 5.6 | G48: 728.5 | H48: 27 | I48: 76.7 | J48: 6.9 | K48: 6.36 | L48: 27.4 | M48: 92.2 | N48: 72.7 | O48: 80.9 | P48: Sprinkler | Q48: 194 | R48: 4.7 | S48: 0.71 | T48: 2.63 | U48: 14.73 | V48: 53568 | W48: 337133 | X48: 789057 | Y48: 451924 | Z48: 3052 | AA48: 4.826 | AB48: 63.2
A49: SF10048 | B49: Punjab | C49: Ludhiana | D49: Sugarcane | E49: Zaid | F49: 7.68 | G49: 90 | H49: 31.9 | I49: 52.7 | J49: 9.8 | K49: 6.51 | L49: 18.3 | M49: 164 | N49: 59.6 | O49: 54.9 | P49: Sprinkler | Q49: 136.9 | R49: 8.04 | S49: 0.76 | T49: 36.69 | U49: 281.78 | V49: 3682 | W49: 480826 | X49: 1037514 | Y49: 556688 | Z49: 13263 | AA49: 21.246 | AB49: 30
A50: SF10049 | B50: Andhra Pradesh | C50: Erode | D50: Chilli | E50: Zaid | F50: 5.52 | G50: 91.3 | H50: 34.1 | I50: 63 | J50: 7.2 | K50: 5.55 | L50: 20.9 | M50: 124.8 | N50: 75.2 | O50: 130.8 | P50: Rainfed | Q50: 207.3 | R50: 4.96 | S50: 0.87 | T50: 0.3 | U50: 1.66 | V50: 102697 | W50: 376564 | X50: 170477 | Y50: -206087 | Z50: 1257 | AA50: 1.321 | AB50: 43.9
A51: SF10050 | B51: Madhya Pradesh | C51: Erode | D51: Rice | E51: Rabi | F51: 8.8 | G51: 792.2 | H51: 21.5 | I51: 51.4 | J51: 8 | K51: 7.8 | L51: 21.8 | M51: 104.1 | N51: 61.9 | O51: 82.3 | P51: Flood | Q51: 223.7 | R51: 6.7 | S51: 0.7 | T51: 0.76 | U51: 6.69 | V51: 19703 | W51: 741670 | X51: 131813 | Y51: -609857 | Z51: 15881 | AA51: 0.421 | AB51: 53.6
A52: SF10051 | B52: Telangana | C52: Warangal | D52: Rice | E52: Zaid | F52: 9.82 | G52: 227.2 | H52: 29.5 | I52: 63.5 | J52: 7.6 | K52: 6.81 | L52: 17.8 | M52: 122.5 | N52: 54.9 | O52: 97 | P52: Flood | Q52: 162.7 | R52: 0.62 | S52: 0.78 | T52: 2.87 | U52: 28.18 | V52: 21316 | W52: 534995 | X52: 600685 | Y52: 65690 | Z52: 16682 | AA52: 1.689 | AB52: 49.4
A53: SF10052 | B53: Andhra Pradesh | C53: Rajkot | D53: Pulses | E53: Rabi | F53: 8.61 | G53: 80 | H53: 24.8 | I53: 60.9 | J53: 7.5 | K53: 5.43 | L53: 28 | M53: 107.1 | N53: 46.4 | O53: 137.6 | P53: Sprinkler | Q53: 178.1 | R53: 4.92 | S53: 1 | T53: 0.3 | U53: 2.58 | V53: 71065 | W53: 492155 | X53: 183348 | Y53: -308807 | Z53: 3106 | AA53: 0.831 | AB53: 40.2
A54: SF10053 | B54: Gujarat | C54: Indore | D54: Rice | E54: Zaid | F54: 11.52 | G54: 206.2 | H54: 34.3 | I54: 50.3 | J54: 10 | K54: 7.01 | L54: 32.7 | M54: 106.7 | N54: 50.4 | O54: 98.1 | P54: Flood | Q54: 112.7 | R54: 6.15 | S54: 0.87 | T54: 1.69 | U54: 19.47 | V54: 19275 | W54: 674473 | X54: 375284 | Y54: -299189 | Z54: 20211 | AA54: 0.963 | AB54: 18.9
A55: SF10054 | B55: Telangana | C55: Nalgonda | D55: Maize | E55: Kharif | F55: 3.18 | G55: 591.2 | H55: 28.1 | I55: 63.9 | J55: 6.8 | K55: 5.66 | L55: 30.8 | M55: 126.9 | N55: 27.6 | O55: 137.7 | P55: Flood | Q55: 289.5 | R55: 5.4 | S55: 0.77 | T55: 1.11 | U55: 3.53 | V55: 17359 | W55: 254223 | X55: 61277 | Y55: -192946 | Z55: 2327 | AA55: 1.517 | AB55: 39.8
A56: SF10055 | B56: Andhra Pradesh | C56: Raichur | D56: Rice | E56: Rabi | F56: 7.08 | G56: 460 | H56: 22.8 | I56: 57.4 | J56: 8.5 | K56: 7.14 | L56: 19.2 | M56: 125.2 | N56: 30.8 | O56: 126.7 | P56: Flood | Q56: 115.3 | R56: 6.38 | S56: 0.94 | T56: 2.92 | U56: 20.67 | V56: 24229 | W56: 591425 | X56: 500813 | Y56: -90612 | Z56: 16012 | AA56: 1.291 | AB56: 29.2
...

Sheet Cleaning_Reference
A1: Data Cleaning Reference Table
A2: Per-crop yield quartiles, used to impute missing yield values and cap statistical outliers (IQR method).
A3: Source: computed from Raw_Data (Yield_Tonnes_Ha) using pandas .quantile() â€” Q1=25th pct, Q3=75th pct, IQR=Q3-Q1, Upper Bound=Q3+1.5*IQR
A5: Crop | B5: Median_Yield_t_ha | C5: Q1_25pct | D5: Q3_75pct | E5: IQR | F5: Upper_Bound_Cap
A6: Chilli | B6: 1.56 | C6: 0.88 | D6: 2.12 | E6: 1.24 | F6: 3.98
A7: Cotton | B7: 1.24 | C7: 0.85 | D7: 1.6 | E7: 0.75 | F7: 2.73
A8: Groundnut | B8: 1.4 | C8: 0.86 | D8: 1.74 | E8: 0.88 | F8: 3.06
A9: Maize | B9: 2.85 | C9: 1.83 | D9: 3.65 | E9: 1.82 | F9: 6.38
A10: Pulses | B10: 0.94 | C10: 0.57 | D10: 1.24 | E10: 0.67 | F10: 2.24
A11: Rice | B11: 2.46 | C11: 1.59 | D11: 3.33 | E11: 1.74 | F11: 5.94
A12: Sugarcane | B12: 48.03 | C12: 32.51 | D12: 61.92 | E12: 29.42 | F12: 106.05
A13: Wheat | B13: 2.22 | C13: 1.45 | D13: 2.77 | E13: 1.32 | F13: 4.75

Sheet Cleaned_Data
A1: Farm ID | B1: State | C1: District | D1: Crop | E1: Season | F1: Farm Area Hectares | G1: Rainfall mm | H1: Avg Temperature C | I1: Humidity pct | J1: Sunlight Hours Day | K1: Soil pH | L1: Soil Moisture pct | M1: Nitrogen kg ha | N1: Phosphorus kg ha | O1: Potassium kg ha | P1: Irrigation Method | Q1: Fertilizer kg ha | R1: Pesticide Litre ha | S1: Seed Quality Score | T1: Yield Tonnes Ha | U1: Production Tonnes | V1: Market Price INR Tonne | W1: Total Cost INR | X1: Revenue INR | Y1: Profit INR | Z1: Water Used m3 | AA1: Water Efficiency t per 1000m3 | AB1: Disease Pest Risk pct | AC1: Rainfall Imputed | AD1: SoilMoisture Imputed | AE1: Yield Status | AF1: Production Recalculated t
A2: =Raw_Data!A2 -> SF10001 | B2: =Raw_Data!B2 -> Andhra Pradesh | C2: =Raw_Data!C2 -> Rajkot | D2: =Raw_Data!D2 -> Wheat | E2: =Raw_Data!E2 -> Kharif | F2: =Raw_Data!F2 -> 0.53 | G2: =IF(Raw_Data!G2="",ROUND(AVERAGEIFS(Raw_Data!$G$2:$G$4001,Raw_Data!$E$2:$E$4001,E2),1),Raw_Data!G2) -> 486.4 | H2: =Raw_Data!H2 -> 24.3 | I2: =Raw_Data!I2 -> 69.1 | J2: =Raw_Data!J2 -> 5.8 | K2: =Raw_Data!K2 -> 7.14 | L2: =IF(Raw_Data!L2="",ROUND(AVERAGEIFS(Raw_Data!$L$2:$L$4001,Raw_Data!$E$2:$E$4001,E2),1),Raw_Data!L2) -> 32.8 | M2: =Raw_Data!M2 -> 75.8 | N2: =Raw_Data!N2 -> 61.3 | O2: =Raw_Data!O2 -> 91 | P2: =Raw_Data!P2 -> Drip | Q2: =Raw_Data!Q2 -> 242.7 | R2: =Raw_Data!R2 -> 4.33 | S2: =Raw_Data!S2 -> 0.76 | T2: =IF(Raw_Data!T2="",ROUND(AVERAGEIFS(Raw_Data!$T$2:$T$4001,Raw_Data!$E$2:$E$4001,E2,Raw_Data!$D$2:$D$4001,D2),2),IF(Raw_Data!T2>INDEX(Cleaning_Reference!$F$6:$F$13,MATCH(D2,Cleaning_Reference!$A$6:$A$13,0)),INDEX(Cleaning_Reference!$F$6:$F$13,MATCH(D2,Cleaning_Reference!$A$6:$A$13,0)),Raw_Data!T2)) -> 2.46 | U2: =Raw_Data!U2 -> 1.3 | V2: =Raw_Data!V2 -> 23700 | W2: =Raw_Data!W2 -> 42662 | X2: =Raw_Data!X2 -> 30810 | Y2: =Raw_Data!Y2 -> -11852 | Z2: =Raw_Data!Z2 -> 237 | AA2: =Raw_Data!AA2 -> 5.485 | AB2: =Raw_Data!AB2 -> 55.3 | AC2: =IF(Raw_Data!G2="","Yes","No") -> No | AD2: =IF(Raw_Data!L2="","Yes","No") -> No | AE2: =IF(Raw_Data!T2="","Imputed",IF(Raw_Data!T2>INDEX(Cleaning_Reference!$F$6:$F$13,MATCH(D2,Cleaning_Reference!$A$6:$A$13,0)),"Capped","Original")) -> Original | AF2: =ROUND(T2*F2,2) -> 1.3
A3: =Raw_Data!A3 -> SF10002 | B3: =Raw_Data!B3 -> Maharashtra | C3: =Raw_Data!C3 -> Nalgonda | D3: =Raw_Data!D3 -> Maize | E3: =Raw_Data!E3 -> Kharif | F3: =Raw_Data!F3 -> 6.53 | G3: =IF(Raw_Data!G3="",ROUND(AVERAGEIFS(Raw_Data!$G$2:$G$4001,Raw_Data!$E$2:$E$4001,E3),1),Raw_Data!G3) -> 855.4 | H3: =Raw_Data!H3 -> 25.7 | I3: =Raw_Data!I3 -> 78.4 | J3: =Raw_Data!J3 -> 5.1 | K3: =Raw_Data!K3 -> 5.2 | L3: =IF(Raw_Data!L3="",ROUND(AVERAGEIFS(Raw_Data!$L$2:$L$4001,Raw_Data!$E$2:$E$4001,E3),1),Raw_Data!L3) -> 32 | M3: =Raw_Data!M3 -> 82.1 | N3: =Raw_Data!N3 -> 35.4 | O3: =Raw_Data!O3 -> 121.8 | P3: =Raw_Data!P3 -> Flood | Q3: =Raw_Data!Q3 -> 271.4 | R3: =Raw_Data!R3 -> 6.86 | S3: =Raw_Data!S3 -> 0.94 | T3: =IF(Raw_Data!T3="",ROUND(AVERAGEIFS(Raw_Data!$T$2:$T$4001,Raw_Data!$E$2:$E$4001,E3,Raw_Data!$D$2:$D$4001,D3),2),IF(Raw_Data!T3>INDEX(Cleaning_Reference!$F$6:$F$13,MATCH(D3,Cleaning_Reference!$A$6:$A$13,0)),INDEX(Cleaning_Reference!$F$6:$F$13,MATCH(D3,Cleaning_Reference!$A$6:$A$13,0)),Raw_Data!T3)) -> 0.3 | U3: =Raw_Data!U3 -> 1.96 | V3: =Raw_Data!V3 -> 20613 | W3: =Raw_Data!W3 -> 492351 | X3: =Raw_Data!X3 -> 40401 | Y3: =Raw_Data!Y3 -> -451950 | Z3: =Raw_Data!Z3 -> 4953 | AA3: =Raw_Data!AA3 -> 0.396 | AB3: =Raw_Data!AB3 -> 49.9 | AC3: =IF(Raw_Data!G3="","Yes","No") -> No | AD3: =IF(Raw_Data!L3="","Yes","No") -> No | AE3: =IF(Raw_Data!T3="","Imputed",IF(Raw_Data!T3>INDEX(Cleaning_Reference!$F$6:$F$13,MATCH(D3,Cleaning_Reference!$A$6:$A$13,0)),"Capped","Original")) -> Original | AF3: =ROUND(T3*F3,2) -> 1.96
A4: =Raw_Data!A4 -> SF10003 | B4: =Raw_Data!B4 -> Telangana | C4: =Raw_Data!C4 -> Warangal | D4: =Raw_Data!D4 -> Pulses | E4: =Raw_Data!E4 -> Rabi | F4: =Raw_Data!F4 -> 4.86 | G4: =IF(Raw_Data!G4="",ROUND(AVERAGEIFS(Raw_Data!$G$2:$G$4001,Raw_Data!$E$2:$E$4001,E4),1),Raw_Data!G4) -> 455.6 | H4: =Raw_Data!H4 -> 23.9 | I4: =Raw_Data!I4 -> 56.4 | J4: =Raw_Data!J4 -> 10.3 | K4: =Raw_Data!K4 -> 5.82 | L4: =IF(Raw_Data!L4="",ROUND(AVERAGEIFS(Raw_Data!$L$2:$L$4001,Raw_Data!$E$2:$E$4001,E4),1),Raw_Data!L4) -> 8.1 | M4: =Raw_Data!M4 -> 118.5 | N4: =Raw_Data!N4 -> 51.5 | O4: =Raw_Data!O4 -> 117.9 | P4: =Raw_Data!P4 -> Drip | Q4: =Raw_Data!Q4 -> 162.6 | R4: =Raw_Data!R4 -> 6.08 | S4: =Raw_Data!S4 -> 0.98 | T4: =IF(Raw_Data!T4="",ROUND(AVERAGEIFS(Raw_Data!$T$2:$T$4001,Raw_Data!$E$2:$E$4001,E4,Raw_Data!$D$2:$D$4001,D4),2),IF(Raw_Data!T4>INDEX(Cleaning_Reference!$F$6:$F$13,MATCH(D4,Cleaning_Reference!$A$6:$A$13,0)),INDEX(Cleaning_Reference!$F$6:$F$13,MATCH(D4,Cleaning_Reference!$A$6:$A$13,0)),Raw_Data!T4)) -> 0.52 | U4: =Raw_Data!U4 -> 2.53 | V4: =Raw_Data!V4 -> 75283 | W4: =Raw_Data!W4 -> 315210 | X4: =Raw_Data!X4 -> 190466 | Y4: =Raw_Data!Y4 -> -124744 | Z4: =Raw_Data!Z4 -> 1275 | AA4: =Raw_Data!AA4 -> 1.984 | AB4: =Raw_Data!AB4 -> 33.7 | AC4: =IF(Raw_Data!G4="","Yes","No") -> No | AD4: =IF(Raw_Data!L4="","Yes","No") -> No | AE4: =IF(Raw_Data!T4="","Imputed",IF(Raw_Data!T4>INDEX(Cleaning_Reference!$F$6:$F$13,MATCH(D4,Cleaning_Reference!$A$6:$A$13,0)),"Capped","Original")) -> Original | AF4: =ROUND(T4*F4,2) -> 2.53
A5: =Raw_Data!A5 -> SF10004 | B5: =Raw_Data!B5 -> Telangana | C5: =Raw_Data!C5 -> Indore | D5: =Raw_Data!D5 -> Rice | E5: =Raw_Data!E5 -> Kharif | F5: =Raw_Data!F5 -> 4.5 | G5: =IF(Raw_Data!G5="",ROUND(AVERAGEIFS(Raw_Data!$G$2:$G$4001,Raw_Data!$E$2:$E$4001,E5),1),Raw_Data!G5) -> 753.2 | H5: =Raw_Data!H5 -> 29.7 | I5: =Raw_Data!I5 -> 65.2 | J5: =Raw_Data!J5 -> 6.3 | K5: =Raw_Data!K5 -> 5.98 | L5: =IF(Raw_Data!L5="",ROUND(AVERAGEIFS(Raw_Data!$L$2:$L$4001,Raw_Data!$E$2:$E$4001,E5),1),Raw_Data!L5) -> 23.7 | M5: =Raw_Data!M5 -> 138.6 | N5: =Raw_Data!N5 -> 55.6 | O5: =Raw_Data!O5 -> 115.5 | P5: =Raw_Data!P5 -> Rainfed | Q5: =Raw_Data!Q5 -> 182.2 | R5: =Raw_Data!R5 -> 6.39 | S5: =Raw_Data!S5 -> 0.74 | T5: =IF(Raw_Data!T5="",ROUND(AVERAGEIFS(Raw_Data!$T$2:$T$4001,Raw_Data!$E$2:$E$4001,E5,Raw_Data!$D$2:$D$4001,D5),2),IF(Raw_Data!T5>INDEX(Cleaning_Reference!$F$6:$F$13,MATCH(D5,Cleaning_Reference!$A$6:$A$13,0)),INDEX(Cleaning_Reference!$F$6:$F$13,MATCH(D5,Cleaning_Reference!$A$6:$A$13,0)),Raw_Data!T5)) -> 1.84 | U5: =Raw_Data!U5 -> 8.28 | V5: =Raw_Data!V5 -> 24244 | W5: =Raw_Data!W5 -> 296444 | X5: =Raw_Data!X5 -> 200740 | Y5: =Raw_Data!Y5 -> -95704 | Z5: =Raw_Data!Z5 -> 3834 | AA5: =Raw_Data!AA5 -> 2.16 | AB5: =Raw_Data!AB5 -> 50.6 | AC5: =IF(Raw_Data!G5="","Yes","No") -> No | AD5: =IF(Raw_Data!L5="","Yes","No") -> No | AE5: =IF(Raw_Data!T5="","Imputed",IF(Raw_Data!T5>INDEX(Cleaning_Reference!$F$6:$F$13,MATCH(D5,Cleaning_Reference!$A$6:$A$13,0)),"Capped","Original")) -> Original | AF5: =ROUND(T5*F5,2) -> 8.28
A6: =Raw_Data!A6 -> SF10005 | B6: =Raw_Data!B6 -> Karnataka | C6: =Raw_Data!C6 -> Ludhiana | D6: =Raw_Data!D6 -> Maize | E6: =Raw_Data!E6 -> Zaid | F6: =Raw_Data!F6 -> 4.21 | G6: =IF(Raw_Data!G6="",ROUND(AVERAGEIFS(Raw_Data!$G$2:$G$4001,Raw_Data!$E$2:$E$4001,E6),1),Raw_Data!G6) -> 101.6 | H6: =Raw_Data!H6 -> 34.1 | I6: =Raw_Data!I6 -> 55.2 | J6: =Raw_Data!J6 -> 6.5 | K6: =Raw_Data!K6 -> 6.9 | L6: =IF(Raw_Data!L6="",ROUND(AVERAGEIFS(Raw_Data!$L$2:$L$4001,Raw_Data!$E$2:$E$4001,E6),1),Raw_Data!L6) -> 29.3 | M6: =Raw_Data!M6 -> 124.1 | N6: =Raw_Data!N6 -> 69 | O6: =Raw_Data!O6 -> 121.4 | P6: =Raw_Data!P6 -> Flood | Q6: =Raw_Data!Q6 -> 244.9 | R6: =Raw_Data!R6 -> 7.61 | S6: =Raw_Data!S6 -> 0.9 | T6: =IF(Raw_Data!T6="",ROUND(AVERAGEIFS(Raw_Data!$T$2:$T$4001,Raw_Data!$E$2:$E$4001,E6,Raw_Data!$D$2:$D$4001,D6),2),IF(Raw_Data!T6>INDEX(Cleaning_Reference!$F$6:$F$13,MATCH(D6,Cleaning_Reference!$A$6:$A$13,0)),INDEX(Cleaning_Reference!$F$6:$F$13,MATCH(D6,Cleaning_Reference!$A$6:$A$13,0)),Raw_Data!T6)) -> 2.21 | U6: =Raw_Data!U6 -> 9.3 | V6: =Raw_Data!V6 -> 20818 | W6: =Raw_Data!W6 -> 337959 | X6: =Raw_Data!X6 -> 193607 | Y6: =Raw_Data!Y6 -> -144352 | Z6: =Raw_Data!Z6 -> 3287 | AA6: =Raw_Data!AA6 -> 2.829 | AB6: =Raw_Data!AB6 -> 32.3 | AC6: =IF(Raw_Data!G6="","Yes","No") -> No | AD6: =IF(Raw_Data!L6="","Yes","No") -> No | AE6: =IF(Raw_Data!T6="","Imputed",IF(Raw_Data!T6>INDEX(Cleaning_Reference!$F$6:$F$13,MATCH(D6,Cleaning_Reference!$A$6:$A$13,0)),"Capped","Original")) -> Original | AF6: =ROUND(T6*F6,2) -> 9.3
A7: =Raw_Data!A7 -> SF10006 | B7: =Raw_Data!B7 -> Gujarat | C7: =Raw_Data!C7 -> Raichur | D7: =Raw_Data!D7 -> Pulses | E7: =Raw_Data!E7 -> Zaid | F7: =Raw_Data!F7 -> 5.46 | G7: =IF(Raw_Data!G7="",ROUND(AVERAGEIFS(Raw_Data!$G$2:$G$4001,Raw_Data!$E$2:$E$4001,E7),1),Raw_Data!G7) -> 356 | H7: =Raw_Data!H7 -> 33.6 | I7: =Raw_Data!I7 -> 49 | J7: =Raw_Data!J7 -> 8.3 | K7: =Raw_Data!K7 -> 6.93 | L7: =IF(Raw_Data!L7="",ROUND(AVERAGEIFS(Raw_Data!$L$2:$L$4001,Raw_Data!$E$2:$E$4001,E7),1),Raw_Data!L7) -> 11.4 | M7: =Raw_Data!M7 -> 105.1 | N7: =Raw_Data!N7 -> 34.7 | O7: =Raw_Data!O7 -> 78.7 | P7: =Raw_Data!P7 -> Rainfed | Q7: =Raw_Data!Q7 -> 58.8 | R7: =Raw_Data!R7 -> 4.48 | S7: =Raw_Data!S7 -> 0.89 | T7: =IF(Raw_Data!T7="",ROUND(AVERAGEIFS(Raw_Data!$T$2:$T$4001,Raw_Data!$E$2:$E$4001,E7,Raw_Data!$D$2:$D$4001,D7),2),IF(Raw_Data!T7>INDEX(Cleaning_Reference!$F$6:$F$13,MATCH(D7,Cleaning_Reference!$A$6:$A$13,0)),INDEX(Cleaning_Reference!$F$6:$F$13,MATCH(D7,Cleaning_Reference!$A$6:$A$13,0)),Raw_Data!T7)) -> 0.72 | U7: =Raw_Data!U7 -> 3.93 | V7: =Raw_Data!V7 -> 68593 | W7: =Raw_Data!W7 -> 302333 | X7: =Raw_Data!X7 -> 269570 | Y7: =Raw_Data!Y7 -> -32763 | Z7: =Raw_Data!Z7 -> 1093 | AA7: =Raw_Data!AA7 -> 3.596 | AB7: =Raw_Data!AB7 -> 57.1 | AC7: =IF(Raw_Data!G7="","Yes","No") -> No | AD7: =IF(Raw_Data!L7="","Yes","No") -> No | AE7: =IF(Raw_Data!T7="","Imputed",IF(Raw_Data!T7>INDEX(Cleaning_Reference!$F$6:$F$13,MATCH(D7,Cleaning_Reference!$A$6:$A$13,0)),"Capped","Original")) -> Original | AF7: =ROUND(T7*F7,2) -> 3.93
A8: =Raw_Data!A8 -> SF10007 | B8: =Raw_Data!B8 -> Telangana | C8: =Raw_Data!C8 -> Warangal | D8: =Raw_Data!D8 -> Wheat | E8: =Raw_Data!E8 -> Rabi | F8: =Raw_Data!F8 -> 8.13 | G8: =IF(Raw_Data!G8="",ROUND(AVERAGEIFS(Raw_Data!$G$2:$G$4001,Raw_Data!$E$2:$E$4001,E8),1),Raw_Data!G8) -> 432.2 | H8: =Raw_Data!H8 -> 23.5 | I8: =Raw_Data!I8 -> 50.8 | J8: =Raw_Data!J8 -> 9.5 | K8: =Raw_Data!K8 -> 6.96 | L8: =IF(Raw_Data!L8="",ROUND(AVERAGEIFS(Raw_Data!$L$2:$L$4001,Raw_Data!$E$2:$E$4001,E8),1),Raw_Data!L8) -> 24.7 | M8: =Raw_Data!M8 -> 115.8 | N8: =Raw_Data!N8 -> 69.4 | O8: =Raw_Data!O8 -> 109.8 | P8: =Raw_Data!P8 -> Rainfed | Q8: =Raw_Data!Q8 -> 181.6 | R8: =Raw_Data!R8 -> 7.99 | S8: =Raw_Data!S8 -> 0.87 | T8: =IF(Raw_Data!T8="",ROUND(AVERAGEIFS(Raw_Data!$T$2:$T$4001,Raw_Data!$E$2:$E$4001,E8,Raw_Data!$D$2:$D$4001,D8),2),IF(Raw_Data!T8>INDEX(Cleaning_Reference!$F$6:$F$13,MATCH(D8,Cleaning_Reference!$A$6:$A$13,0)),INDEX(Cleaning_Reference!$F$6:$F$13,MATCH(D8,Cleaning_Reference!$A$6:$A$13,0)),Raw_Data!T8)) -> 2.53 | U8: =Raw_Data!U8 -> 20.57 | V8: =Raw_Data!V8 -> 22951 | W8: =Raw_Data!W8 -> 513341 | X8: =Raw_Data!X8 -> 472102 | Y8: =Raw_Data!Y8 -> -41239 | Z8: =Raw_Data!Z8 -> 2368 | AA8: =Raw_Data!AA8 -> 8.687 | AB8: =Raw_Data!AB8 -> 31.6 | AC8: =IF(Raw_Data!G8="","Yes","No") -> No | AD8: =IF(Raw_Data!L8="","Yes","No") -> No | AE8: =IF(Raw_Data!T8="","Imputed",IF(Raw_Data!T8>INDEX(Cleaning_Reference!$F$6:$F$13,MATCH(D8,Cleaning_Reference!$A$6:$A$13,0)),"Capped","Original")) -> Original | AF8: =ROUND(T8*F8,2) -> 20.57
A9: =Raw_Data!A9 -> SF10008 | B9: =Raw_Data!B9 -> Tamil Nadu | C9: =Raw_Data!C9 -> Ludhiana | D9: =Raw_Data!D9 -> Pulses | E9: =Raw_Data!E9 -> Kharif | F9: =Raw_Data!F9 -> 5.34 | G9: =IF(Raw_Data!G9="",ROUND(AVERAGEIFS(Raw_Data!$G$2:$G$4001,Raw_Data!$E$2:$E$4001,E9),1),Raw_Data!G9) -> 860.2 | H9: =Raw_Data!H9 -> 29 | I9: =Raw_Data!I9 -> 64.9 | J9: =Raw_Data!J9 -> 7.9 | K9: =Raw_Data!K9 -> 6.09 | L9: =IF(Raw_Data!L9="",ROUND(AVERAGEIFS(Raw_Data!$L$2:$L$4001,Raw_Data!$E$2:$E$4001,E9),1),Raw_Data!L9) -> 36.9 | M9: =Raw_Data!M9 -> 112.7 | N9: =Raw_Data!N9 -> 60.9 | O9: =Raw_Data!O9 -> 115.9 | P9: =Raw_Data!P9 -> Sprinkler | Q9: =Raw_Data!Q9 -> 245.8 | R9: =Raw_Data!R9 -> 5.89 | S9: =Raw_Data!S9 -> 0.7 | T9: =IF(Raw_Data!T9="",ROUND(AVERAGEIFS(Raw_Data!$T$2:$T$4001,Raw_Data!$E$2:$E$4001,E9,Raw_Data!$D$2:$D$4001,D9),2),IF(Raw_Data!T9>INDEX(Cleaning_Reference!$F$6:$F$13,MATCH(D9,Cleaning_Reference!$A$6:$A$13,0)),INDEX(Cleaning_Reference!$F$6:$F$13,MATCH(D9,Cleaning_Reference!$A$6:$A$13,0)),Raw_Data!T9)) -> 1.18 | U9: =Raw_Data!U9 -> 6.3 | V9: =Raw_Data!V9 -> 70042 | W9: =Raw_Data!W9 -> 436200 | X9: =Raw_Data!X9 -> 441265 | Y9: =Raw_Data!Y9 -> 5065 | Z9: =Raw_Data!Z9 -> 1704 | AA9: =Raw_Data!AA9 -> 3.697 | AB9: =Raw_Data!AB9 -> 54.2 | AC9: =IF(Raw_Data!G9="","Yes","No") -> No | AD9: =IF(Raw_Data!L9="","Yes","No") -> No | AE9: =IF(Raw_Data!T9="","Imputed",IF(Raw_Data!T9>INDEX(Cleaning_Reference!$F$6:$F$13,MATCH(D9,Cleaning_Reference!$A$6:$A$13,0)),"Capped","Original")) -> Original | AF9: =ROUND(T9*F9,2) -> 6.3
A10: =Raw_Data!A10 -> SF10009 | B10: =Raw_Data!B10 -> Karnataka | C10: =Raw_Data!C10 -> Guntur | D10: =Raw_Data!D10 -> Cotton | E10: =Raw_Data!E10 -> Zaid | F10: =Raw_Data!F10 -> 6.98 | G10: =IF(Raw_Data!G10="",ROUND(AVERAGEIFS(Raw_Data!$G$2:$G$4001,Raw_Data!$E$2:$E$4001,E10),1),Raw_Data!G10) -> 624.7 | H10: =Raw_Data!H10 -> 33.4 | I10: =Raw_Data!I10 -> 46.8 | J10: =Raw_Data!J10 -> 7.9 | K10: =Raw_Data!K10 -> 6.41 | L10: =IF(Raw_Data!L10="",ROUND(AVERAGEIFS(Raw_Data!$L$2:$L$4001,Raw_Data!$E$2:$E$4001,E10),1),Raw_Data!L10) -> 12.3 | M10: =Raw_Data!M10 -> 66.9 | N10: =Raw_Data!N10 -> 47.6 | O10: =Raw_Data!O10 -> 134.2 | P10: =Raw_Data!P10 -> Sprinkler | Q10: =Raw_Data!Q10 -> 190.7 | R10: =Raw_Data!R10 -> 2.21 | S10: =Raw_Data!S10 -> 0.88 | T10: =IF(Raw_Data!T10="",ROUND(AVERAGEIFS(Raw_Data!$T$2:$T$4001,Raw_Data!$E$2:$E$4001,E10,Raw_Data!$D$2:$D$4001,D10),2),IF(Raw_Data!T10>INDEX(Cleaning_Reference!$F$6:$F$13,MATCH(D10,Cleaning_Reference!$A$6:$A$13,0)),INDEX(Cleaning_Reference!$F$6:$F$13,MATCH(D10,Cleaning_Reference!$A$6:$A$13,0)),Raw_Data!T10)) -> 1.53 | U10: =Raw_Data!U10 -> 10.68 | V10: =Raw_Data!V10 -> 70771 | W10: =Raw_Data!W10 -> 525129 | X10: =Raw_Data!X10 -> 755834 | Y10: =Raw_Data!Y10 -> 230705 | Z10: =Raw_Data!Z10 -> 5079 | AA10: =Raw_Data!AA10 -> 2.103 | AB10: =Raw_Data!AB10 -> 54.7 | AC10: =IF(Raw_Data!G10="","Yes","No") -> No | AD10: =IF(Raw_Data!L10="","Yes","No") -> No | AE10: =IF(Raw_Data!T10="","Imputed",IF(Raw_Data!T10>INDEX(Cleaning_Reference!$F$6:$F$13,MATCH(D10,Cleaning_Reference!$A$6:$A$13,0)),"Capped","Original")) -> Original | AF10: =ROUND(T10*F10,2) -> 10.68
A11: =Raw_Data!A11 -> SF10010 | B11: =Raw_Data!B11 -> Tamil Nadu | C11: =Raw_Data!C11 -> Raichur | D11: =Raw_Data!D11 -> Chilli | E11: =Raw_Data!E11 -> Rabi | F11: =Raw_Data!F11 -> 13.69 | G11: =IF(Raw_Data!G11="",ROUND(AVERAGEIFS(Raw_Data!$G$2:$G$4001,Raw_Data!$E$2:$E$4001,E11),1),Raw_Data!G11) -> 415.8 | H11: =Raw_Data!H11 -> 22.3 | I11: =Raw_Data!I11 -> 57.3 | J11: =Raw_Data!J11 -> 8.6 | K11: =Raw_Data!K11 -> 6.6 | L11: =IF(Raw_Data!L11="",ROUND(AVERAGEIFS(Raw_Data!$L$2:$L$4001,Raw_Data!$E$2:$E$4001,E11),1),Raw_Data!L11) -> 23.3 | M11: =Raw_Data!M11 -> 117.9 | N11: =Raw_Data!N11 -> 37.2 | O11: =Raw_Data!O11 -> 116.6 | P11: =Raw_Data!P11 -> Drip | Q11: =Raw_Data!Q11 -> 168.8 | R11: =Raw_Data!R11 -> 7.29 | S11: =Raw_Data!S11 -> 0.7 | T11: =IF(Raw_Data!T11="",ROUND(AVERAGEIFS(Raw_Data!$T$2:$T$4001,Raw_Data!$E$2:$E$4001,E11,Raw_Data!$D$2:$D$4001,D11),2),IF(Raw_Data!T11>INDEX(Cleaning_Reference!$F$6:$F$13,MATCH(D11,Cleaning_Reference!$A$6:$A$13,0)),INDEX(Cleaning_Reference!$F$6:$F$13,MATCH(D11,Cleaning_Reference!$A$6:$A$13,0)),Raw_Data!T11)) -> 2.29 | U11: =Raw_Data!U11 -> 31.35 | V11: =Raw_Data!V11 -> 94383 | W11: =Raw_Data!W11 -> 1004072 | X11: =Raw_Data!X11 -> 2958907 | Y11: =Raw_Data!Y11 -> 1954835 | Z11: =Raw_Data!Z11 -> 5984 | AA11: =Raw_Data!AA11 -> 5.239 | AB11: =Raw_Data!AB11 -> 41.7 | AC11: =IF(Raw_Data!G11="","Yes","No") -> No | AD11: =IF(Raw_Data!L11="","Yes","No") -> No | AE11: =IF(Raw_Data!T11="","Imputed",IF(Raw_Data!T11>INDEX(Cleaning_Reference!$F$6:$F$13,MATCH(D11,Cleaning_Reference!$A$6:$A$13,0)),"Capped","Original")) -> Original | AF11: =ROUND(T11*F11,2) -> 31.35
A12: =Raw_Data!A12 -> SF10011 | B12: =Raw_Data!B12 -> Maharashtra | C12: =Raw_Data!C12 -> Krishna | D12: =Raw_Data!D12 -> Wheat | E12: =Raw_Data!E12 -> Rabi | F12: =Raw_Data!F12 -> 4.7 | G12: =IF(Raw_Data!G12="",ROUND(AVERAGEIFS(Raw_Data!$G$2:$G$4001,Raw_Data!$E$2:$E$4001,E12),1),Raw_Data!G12) -> 390.8 | H12: =Raw_Data!H12 -> 24.5 | I12: =Raw_Data!I12 -> 43.5 | J12: =Raw_Data!J12 -> 7.8 | K12: =Raw_Data!K12 -> 5.93 | L12: =IF(Raw_Data!L12="",ROUND(AVERAGEIFS(Raw_Data!$L$2:$L$4001,Raw_Data!$E$2:$E$4001,E12),1),Raw_Data!L12) -> 25.2 | M12: =Raw_Data!M12 -> 137.9 | N12: =Raw_Data!N12 -> 31.4 | O12: =Raw_Data!O12 -> 70 | P12: =Raw_Data!P12 -> Sprinkler | Q12: =Raw_Data!Q12 -> 224.4 | R12: =Raw_Data!R12 -> 5.9 | S12: =Raw_Data!S12 -> 0.89 | T12: =IF(Raw_Data!T12="",ROUND(AVERAGEIFS(Raw_Data!$T$2:$T$4001,Raw_Data!$E$2:$E$4001,E12,Raw_Data!$D$2:$D$4001,D12),2),IF(Raw_Data!T12>INDEX(Cleaning_Reference!$F$6:$F$13,MATCH(D12,Cleaning_Reference!$A$6:$A$13,0)),INDEX(Cleaning_Reference!$F$6:$F$13,MATCH(D12,Cleaning_Reference!$A$6:$A$13,0)),Raw_Data!T12)) -> 1.44 | U12: =Raw_Data!U12 -> 6.77 | V12: =Raw_Data!V12 -> 20806 | W12: =Raw_Data!W12 -> 289759 | X12: =Raw_Data!X12 -> 140857 | Y12: =Raw_Data!Y12 -> -148902 | Z12: =Raw_Data!Z12 -> 2371 | AA12: =Raw_Data!AA12 -> 2.855 | AB12: =Raw_Data!AB12 -> 33.5 | AC12: =IF(Raw_Data!G12="","Yes","No") -> No | AD12: =IF(Raw_Data!L12="","Yes","No") -> No | AE12: =IF(Raw_Data!T12="","Imputed",IF(Raw_Data!T12>INDEX(Cleaning_Reference!$F$6:$F$13,MATCH(D12,Cleaning_Reference!$A$6:$A$13,0)),"Capped","Original")) -> Original | AF12: =ROUND(T12*F12,2) -> 6.77
A13: =Raw_Data!A13 -> SF10012 | B13: =Raw_Data!B13 -> Telangana | C13: =Raw_Data!C13 -> Rajkot | D13: =Raw_Data!D13 -> Maize | E13: =Raw_Data!E13 -> Rabi | F13: =Raw_Data!F13 -> 14.07 | G13: =IF(Raw_Data!G13="",ROUND(AVERAGEIFS(Raw_Data!$G$2:$G$4001,Raw_Data!$E$2:$E$4001,E13),1),Raw_Data!G13) -> 315.3 | H13: =Raw_Data!H13 -> 24.2 | I13: =Raw_Data!I13 -> 53.7 | J13: =Raw_Data!J13 -> 5.9 | K13: =Raw_Data!K13 -> 5.87 | L13: =IF(Raw_Data!L13="",ROUND(AVERAGEIFS(Raw_Data!$L$2:$L$4001,Raw_Data!$E$2:$E$4001,E13),1),Raw_Data!L13) -> 29.4 | M13: =Raw_Data!M13 -> 100.6 | N13: =Raw_Data!N13 -> 50.8 | O13: =Raw_Data!O13 -> 65.8 | P13: =Raw_Data!P13 -> Drip | Q13: =Raw_Data!Q13 -> 178.7 | R13: =Raw_Data!R13 -> 5.34 | S13: =Raw_Data!S13 -> 0.71 | T13: =IF(Raw_Data!T13="",ROUND(AVERAGEIFS(Raw_Data!$T$2:$T$4001,Raw_Data!$E$2:$E$4001,E13,Raw_Data!$D$2:$D$4001,D13),2),IF(Raw_Data!T13>INDEX(Cleaning_Reference!$F$6:$F$13,MATCH(D13,Cleaning_Reference!$A$6:$A$13,0)),INDEX(Cleaning_Reference!$F$6:$F$13,MATCH(D13,Cleaning_Reference!$A$6:$A$13,0)),Raw_Data!T13)) -> 1.36 | U13: =Raw_Data!U13 -> 19.14 | V13: =Raw_Data!V13 -> 20120 | W13: =Raw_Data!W13 -> 964512 | X13: =Raw_Data!X13 -> 385097 | Y13: =Raw_Data!Y13 -> -579415 | Z13: =Raw_Data!Z13 -> 7467 | AA13: =Raw_Data!AA13 -> 2.563 | AB13: =Raw_Data!AB13 -> 35 | AC13: =IF(Raw_Data!G13="","Yes","No") -> No | AD13: =IF(Raw_Data!L13="","Yes","No") -> No | AE13: =IF(Raw_Data!T13="","Imputed",IF(Raw_Data!T13>INDEX(Cleaning_Reference!$F$6:$F$13,MATCH(D13,Cleaning_Reference!$A$6:$A$13,0)),"Capped","Original")) -> Original | AF13: =ROUND(T13*F13,2) -> 19.14
... A4001: =Raw_Data!A4001 -> SF14000 | B4001: =Raw_Data!B4001 -> Punjab | C4001: =Raw_Data!C4001 -> Nashik | D4001: =Raw_Data!D4001 -> Wheat | E4001: =Raw_Data!E4001 -> Kharif | F4001: =Raw_Data!F4001 -> 3.31 | G4001: =IF(Raw_Data!G4001="",ROUND(AVERAGEIFS(Raw_Data!$G$2:$G$4001,Raw_Data!$E$2:$E$4001,E4001),1),Raw_Data!G4001) -> 984.3 | H4001: =Raw_Data!H4001 -> 25.8 | I4001: =Raw_Data!I4001 -> 77.2 | J4001: =Raw_Data!J4001 -> 5.9 | K4001: =Raw_Data!K4001 -> 6.16 | L4001: =IF(Raw_Data!L4001="",ROUND(AVERAGEIFS(Raw_Data!$L$2:$L$4001,Raw_Data!$E$2:$E$4001,E4001),1),Raw_Data!L4001) -> 35.7 | M4001: =Raw_Data!M4001 -> 137.1 | N4001: =Raw_Data!N4001 -> 92.6 | O4001: =Raw_Data!O4001 -> 145.5 | P4001: =Raw_Data!P4001 -> Sprinkler | Q4001: =Raw_Data!Q4001 -> 205.9 | R4001: =Raw_Data!R4001 -> 6.72 | S4001: =Raw_Data!S4001 -> 0.99 | T4001: =IF(Raw_Data!T4001="",ROUND(AVERAGEIFS(Raw_Data!$T$2:$T$4001,Raw_Data!$E$2:$E$4001,E4001,Raw_Data!$D$2:$D$4001,D4001),2),IF(Raw_Data!T4001>INDEX(Cleaning_Reference!$F$6:$F$13,MATCH(D4001,Cleaning_Reference!$A$6:$A$13,0)),INDEX(Cleaning_Reference!$F$6:$F$13,MATCH(D4001,Cleaning_Reference!$A$6:$A$13,0)),Raw_Data!T4001)) -> 2.36 | U4001: =Raw_Data!U4001 -> 7.81 | V4001: =Raw_Data!V4001 -> 28812 | W4001: =Raw_Data!W4001 -> 263872 | X4001: =Raw_Data!X4001 -> 225022 | Y4001: =Raw_Data!Y4001 -> -38850 | Z4001: =Raw_Data!Z4001 -> 1800 | AA4001: =Raw_Data!AA4001 -> 4.339 | AB4001: =Raw_Data!AB4001 -> 62.3 | AC4001: =IF(Raw_Data!G4001="","Yes","No") -> No | AD4001: =IF(Raw_Data!L4001="","Yes","No") -> No | AE4001: =IF(Raw_Data!T4001="","Imputed",IF(Raw_Data!T4001>INDEX(Cleaning_Reference!$F$6:$F$13,MATCH(D4001,Cleaning_Reference!$A$6:$A$13,0)),"Capped","Original")) -> Original | AF4001: =ROUND(T4001*F4001,2) -> 7.81

Sheet Season_Summary
A1: Seasonal Performance Summary
A2: Key metrics averaged/summed across all farms, by season (source: Cleaned_Data)
A4: Metric | B4: Kharif | C4: Rabi | D4: Zaid
A5: Number of Farms | B5: =COUNTIF(Cleaned_Data!$E$2:$E$4001,"Kharif") -> 1779 | C5: =COUNTIF(Cleaned_Data!$E$2:$E$4001,"Rabi") -> 1627 | D5: =COUNTIF(Cleaned_Data!$E$2:$E$4001,"Zaid") -> 594
A6: Avg Farm Area (ha) | B6: =AVERAGEIFS(Cleaned_Data!$F$2:$F$4001,Cleaned_Data!$E$2:$E$4001,"Kharif") -> 7.9449241 | C6: =AVERAGEIFS(Cleaned_Data!$F$2:$F$4001,Cleaned_Data!$E$2:$E$4001,"Rabi") -> 7.7522065 | D6: =AVERAGEIFS(Cleaned_Data!$F$2:$F$4001,Cleaned_Data!$E$2:$E$4001,"Zaid") -> 8.0912458
A7: Avg Rainfall (mm) | B7: =AVERAGEIFS(Cleaned_Data!$G$2:$G$4001,Cleaned_Data!$E$2:$E$4001,"Kharif") -> 852.08437 | C7: =AVERAGEIFS(Cleaned_Data!$G$2:$G$4001,Cleaned_Data!$E$2:$E$4001,"Rabi") -> 436.00012 | D7: =AVERAGEIFS(Cleaned_Data!$G$2:$G$4001,Cleaned_Data!$E$2:$E$4001,"Zaid") -> 299.42138
A8: Avg Temperature (C) | B8: =AVERAGEIFS(Cleaned_Data!$H$2:$H$4001,Cleaned_Data!$E$2:$E$4001,"Kharif") -> 28.454019 | C8: =AVERAGEIFS(Cleaned_Data!$H$2:$H$4001,Cleaned_Data!$E$2:$E$4001,"Rabi") -> 23.489183 | D8: =AVERAGEIFS(Cleaned_Data!$H$2:$H$4001,Cleaned_Data!$E$2:$E$4001,"Zaid") -> 31.042088
A9: Avg Humidity (%) | B9: =AVERAGEIFS(Cleaned_Data!$I$2:$I$4001,Cleaned_Data!$E$2:$E$4001,"Kharif") -> 71.812591 | C9: =AVERAGEIFS(Cleaned_Data!$I$2:$I$4001,Cleaned_Data!$E$2:$E$4001,"Rabi") -> 57.893178 | D9: =AVERAGEIFS(Cleaned_Data!$I$2:$I$4001,Cleaned_Data!$E$2:$E$4001,"Zaid") -> 52.012121
A10: Avg Sunlight (hrs/day) | B10: =AVERAGEIFS(Cleaned_Data!$J$2:$J$4001,Cleaned_Data!$E$2:$E$4001,"Kharif") -> 6.7933671 | C10: =AVERAGEIFS(Cleaned_Data!$J$2:$J$4001,Cleaned_Data!$E$2:$E$4001,"Rabi") -> 7.5897972 | D10: =AVERAGEIFS(Cleaned_Data!$J$2:$J$4001,Cleaned_Data!$E$2:$E$4001,"Zaid") -> 8.1787879
A11: Avg Soil pH | B11: =AVERAGEIFS(Cleaned_Data!$K$2:$K$4001,Cleaned_Data!$E$2:$E$4001,"Kharif") -> 6.7279933 | C11: =AVERAGEIFS(Cleaned_Data!$K$2:$K$4001,Cleaned_Data!$E$2:$E$4001,"Rabi") -> 6.6737492 | D11: =AVERAGEIFS(Cleaned_Data!$K$2:$K$4001,Cleaned_Data!$E$2:$E$4001,"Zaid") -> 6.6948653
A12: Avg Soil Moisture (%) | B12: =AVERAGEIFS(Cleaned_Data!$L$2:$L$4001,Cleaned_Data!$E$2:$E$4001,"Kharif") -> 31.198426 | C12: =AVERAGEIFS(Cleaned_Data!$L$2:$L$4001,Cleaned_Data!$E$2:$E$4001,"Rabi") -> 24.051014 | D12: =AVERAGEIFS(Cleaned_Data!$L$2:$L$4001,Cleaned_Data!$E$2:$E$4001,"Zaid") -> 19.170539
A13: Avg Fertilizer (kg/ha) | B13: =AVERAGEIFS(Cleaned_Data!$Q$2:$Q$4001,Cleaned_Data!$E$2:$E$4001,"Kharif") -> 187.07797 | C13: =AVERAGEIFS(Cleaned_Data!$Q$2:$Q$4001,Cleaned_Data!$E$2:$E$4001,"Rabi") -> 185.40707 | D13: =AVERAGEIFS(Cleaned_Data!$Q$2:$Q$4001,Cleaned_Data!$E$2:$E$4001,"Zaid") -> 184.63805
A14: Avg Pesticide (L/ha) | B14: =AVERAGEIFS(Cleaned_Data!$R$2:$R$4001,Cleaned_Data!$E$2:$E$4001,"Kharif") -> 5.079747 | C14: =AVERAGEIFS(Cleaned_Data!$R$2:$R$4001,Cleaned_Data!$E$2:$E$4001,"Rabi") -> 5.0246896 | D14: =AVERAGEIFS(Cleaned_Data!$R$2:$R$4001,Cleaned_Data!$E$2:$E$4001,"Zaid") -> 5.1712121
A15: Avg Seed Quality Score | B15: =AVERAGEIFS(Cleaned_Data!$S$2:$S$4001,Cleaned_Data!$E$2:$E$4001,"Kharif") -> 0.82161327 | C15: =AVERAGEIFS(Cleaned_Data!$S$2:$S$4001,Cleaned_Data!$E$2:$E$4001,"Rabi") -> 0.83216964 | D15: =AVERAGEIFS(Cleaned_Data!$S$2:$S$4001,Cleaned_Data!$E$2:$E$4001,"Zaid") -> 0.82316498
A16: Avg Yield (t/ha) | B16: =AVERAGEIFS(Cleaned_Data!$T$2:$T$4001,Cleaned_Data!$E$2:$E$4001,"Kharif") -> 5.6300843 | C16: =AVERAGEIFS(Cleaned_Data!$T$2:$T$4001,Cleaned_Data!$E$2:$E$4001,"Rabi") -> 5.0920897 | D16: =AVERAGEIFS(Cleaned_Data!$T$2:$T$4001,Cleaned_Data!$E$2:$E$4001,"Zaid") -> 4.6372054
A17: Total Production (t) | B17: =SUMIFS(Cleaned_Data!$U$2:$U$4001,Cleaned_Data!$E$2:$E$4001,"Kharif") -> 82387.61 | C17: =SUMIFS(Cleaned_Data!$U$2:$U$4001,Cleaned_Data!$E$2:$E$4001,"Rabi") -> 67498.88 | D17: =SUMIFS(Cleaned_Data!$U$2:$U$4001,Cleaned_Data!$E$2:$E$4001,"Zaid") -> 23098.35
A18: Avg Market Price (INR/t) | B18: =AVERAGEIFS(Cleaned_Data!$V$2:$V$4001,Cleaned_Data!$E$2:$E$4001,"Kharif") -> 44850.906 | C18: =AVERAGEIFS(Cleaned_Data!$V$2:$V$4001,Cleaned_Data!$E$2:$E$4001,"Rabi") -> 44747.975 | D18: =AVERAGEIFS(Cleaned_Data!$V$2:$V$4001,Cleaned_Data!$E$2:$E$4001,"Zaid") -> 44212.034
A19: Total Revenue (INR) | B19: =SUMIFS(Cleaned_Data!$X$2:$X$4001,Cleaned_Data!$E$2:$E$4001,"Kharif") -> 1264369200 | C19: =SUMIFS(Cleaned_Data!$X$2:$X$4001,Cleaned_Data!$E$2:$E$4001,"Rabi") -> 978682881 | D19: =SUMIFS(Cleaned_Data!$X$2:$X$4001,Cleaned_Data!$E$2:$E$4001,"Zaid") -> 308388111
A20: Total Cost (INR) | B20: =SUMIFS(Cleaned_Data!$W$2:$W$4001,Cleaned_Data!$E$2:$E$4001,"Kharif") -> 946080042 | C20: =SUMIFS(Cleaned_Data!$W$2:$W$4001,Cleaned_Data!$E$2:$E$4001,"Rabi") -> 836012113 | D20: =SUMIFS(Cleaned_Data!$W$2:$W$4001,Cleaned_Data!$E$2:$E$4001,"Zaid") -> 323122177
A21: Total Profit (INR) | B21: =SUMIFS(Cleaned_Data!$Y$2:$Y$4001,Cleaned_Data!$E$2:$E$4001,"Kharif") -> 318289158 | C21: =SUMIFS(Cleaned_Data!$Y$2:$Y$4001,Cleaned_Data!$E$2:$E$4001,"Rabi") -> 142670768 | D21: =SUMIFS(Cleaned_Data!$Y$2:$Y$4001,Cleaned_Data!$E$2:$E$4001,"Zaid") -> -14734066
A22: Avg Profit per Farm (INR) | B22: =AVERAGEIFS(Cleaned_Data!$Y$2:$Y$4001,Cleaned_Data!$E$2:$E$4001,"Kharif") -> 178914.65 | C22: =AVERAGEIFS(Cleaned_Data!$Y$2:$Y$4001,Cleaned_Data!$E$2:$E$4001,"Rabi") -> 87689.47 | D22: =AVERAGEIFS(Cleaned_Data!$Y$2:$Y$4001,Cleaned_Data!$E$2:$E$4001,"Zaid") -> -24804.825
A23: Profit Margin (%) | B23: =B21/B19 -> 0.25173751 | C23: =C21/C19 -> 0.14577834 | D23: =D21/D19 -> -0.047777672
A24: Avg Water Used (m3) | B24: =AVERAGEIFS(Cleaned_Data!$Z$2:$Z$4001,Cleaned_Data!$E$2:$E$4001,"Kharif") -> 6102.2012 | C24: =AVERAGEIFS(Cleaned_Data!$Z$2:$Z$4001,Cleaned_Data!$E$2:$E$4001,"Rabi") -> 5846.9871 | D24: =AVERAGEIFS(Cleaned_Data!$Z$2:$Z$4001,Cleaned_Data!$E$2:$E$4001,"Zaid") -> 6419.8939
A25: Avg Water Efficiency (t/1000m3) | B25: =AVERAGEIFS(Cleaned_Data!$AA$2:$AA$4001,Cleaned_Data!$E$2:$E$4001,"Kharif") -> 5.8918336 | C25: =AVERAGEIFS(Cleaned_Data!$AA$2:$AA$4001,Cleaned_Data!$E$2:$E$4001,"Rabi") -> 5.1861223 | D25: =AVERAGEIFS(Cleaned_Data!$AA$2:$AA$4001,Cleaned_Data!$E$2:$E$4001,"Zaid") -> 4.4132391
A26: Avg Disease/Pest Risk (%) | B26: =AVERAGEIFS(Cleaned_Data!$AB$2:$AB$4001,Cleaned_Data!$E$2:$E$4001,"Kharif") -> 54.467903 | C26: =AVERAGEIFS(Cleaned_Data!$AB$2:$AB$4001,Cleaned_Data!$E$2:$E$4001,"Rabi") -> 40.482114 | D26: =AVERAGEIFS(Cleaned_Data!$AB$2:$AB$4001,Cleaned_Data!$E$2:$E$4001,"Zaid") -> 38.216667
A27: Loss-Making Farms (%) | B27: =COUNTIFS(Cleaned_Data!$E$2:$E$4001,"Kharif",Cleaned_Data!$Y$2:$Y$4001,"<0")/COUNTIF(Cleaned_Data!$E$2:$E$4001,"Kharif") -> 0.42214727 | C27: =COUNTIFS(Cleaned_Data!$E$2:$E$4001,"Rabi",Cleaned_Data!$Y$2:$Y$4001,"<0")/COUNTIF(Cleaned_Data!$E$2:$E$4001,"Rabi") -> 0.51137062 | D27: =COUNTIFS(Cleaned_Data!$E$2:$E$4001,"Zaid",Cleaned_Data!$Y$2:$Y$4001,"<0")/COUNTIF(Cleaned_Data!$E$2:$E$4001,"Zaid") -> 0.64478114

Sheet Season_Crop_Matrix
A1: Average Yield & Profit by Season x Crop
A2: Checks whether seasonal patterns are consistent across crop types
A4: Avg Yield (t/ha)
A5: Crop | B5: Kharif | C5: Rabi | D5: Zaid
A6: Wheat | B6: =IFERROR(AVERAGEIFS(Cleaned_Data!$T$2:$T$4001,Cleaned_Data!$E$2:$E$4001,"Kharif",Cleaned_Data!$D$2:$D$4001,"Wheat"),"n/a") -> 2.2554452 | C6: =IFERROR(AVERAGEIFS(Cleaned_Data!$T$2:$T$4001,Cleaned_Data!$E$2:$E$4001,"Rabi",Cleaned_Data!$D$2:$D$4001,"Wheat"),"n/a") -> 2.0588186 | D6: =IFERROR(AVERAGEIFS(Cleaned_Data!$T$2:$T$4001,Cleaned_Data!$E$2:$E$4001,"Zaid",Cleaned_Data!$D$2:$D$4001,"Wheat"),"n/a") -> 1.7485882
A7: Rice | B7: =IFERROR(AVERAGEIFS(Cleaned_Data!$T$2:$T$4001,Cleaned_Data!$E$2:$E$4001,"Kharif",Cleaned_Data!$D$2:$D$4001,"Rice"),"n/a") -> 2.7076433 | C7: =IFERROR(AVERAGEIFS(Cleaned_Data!$T$2:$T$4001,Cleaned_Data!$E$2:$E$4001,"Rabi",Cleaned_Data!$D$2:$D$4001,"Rice"),"n/a") -> 2.3336131 | D7: =IFERROR(AVERAGEIFS(Cleaned_Data!$T$2:$T$4001,Cleaned_Data!$E$2:$E$4001,"Zaid",Cleaned_Data!$D$2:$D$4001,"Rice"),"n/a") -> 1.9004902
A8: Maize | B8: =IFERROR(AVERAGEIFS(Cleaned_Data!$T$2:$T$4001,Cleaned_Data!$E$2:$E$4001,"Kharif",Cleaned_Data!$D$2:$D$4001,"Maize"),"n/a") -> 2.9664103 | C8: =IFERROR(AVERAGEIFS(Cleaned_Data!$T$2:$T$4001,Cleaned_Data!$E$2:$E$4001,"Rabi",Cleaned_Data!$D$2:$D$4001,"Maize"),"n/a") -> 2.6148498 | D8: =IFERROR(AVERAGEIFS(Cleaned_Data!$T$2:$T$4001,Cleaned_Data!$E$2:$E$4001,"Zaid",Cleaned_Data!$D$2:$D$4001,"Maize"),"n/a") -> 2.297619
A9: Cotton | B9: =IFERROR(AVERAGEIFS(Cleaned_Data!$T$2:$T$4001,Cleaned_Data!$E$2:$E$4001,"Kharif",Cleaned_Data!$D$2:$D$4001,"Cotton"),"n/a") -> 1.372 | C9: =IFERROR(AVERAGEIFS(Cleaned_Data!$T$2:$T$4001,Cleaned_Data!$E$2:$E$4001,"Rabi",Cleaned_Data!$D$2:$D$4001,"Cotton"),"n/a") -> 1.1928856 | D9: =IFERROR(AVERAGEIFS(Cleaned_Data!$T$2:$T$4001,Cleaned_Data!$E$2:$E$4001,"Zaid",Cleaned_Data!$D$2:$D$4001,"Cotton"),"n/a") -> 0.95163043
A10: Pulses | B10: =IFERROR(AVERAGEIFS(Cleaned_Data!$T$2:$T$4001,Cleaned_Data!$E$2:$E$4001,"Kharif",Cleaned_Data!$D$2:$D$4001,"Pulses"),"n/a") -> 1.0360633 | C10: =IFERROR(AVERAGEIFS(Cleaned_Data!$T$2:$T$4001,Cleaned_Data!$E$2:$E$4001,"Rabi",Cleaned_Data!$D$2:$D$4001,"Pulses"),"n/a") -> 0.87187793 | D10: =IFERROR(AVERAGEIFS(Cleaned_Data!$T$2:$T$4001,Cleaned_Data!$E$2:$E$4001,"Zaid",Cleaned_Data!$D$2:$D$4001,"Pulses"),"n/a") -> 0.65209677
A11: Groundnut | B11: =IFERROR(AVERAGEIFS(Cleaned_Data!$T$2:$T$4001,Cleaned_Data!$E$2:$E$4001,"Kharif",Cleaned_Data!$D$2:$D$4001,"Groundnut"),"n/a") -> 1.4836269 | C11: =IFERROR(AVERAGEIFS(Cleaned_Data!$T$2:$T$4001,Cleaned_Data!$E$2:$E$4001,"Rabi",Cleaned_Data!$D$2:$D$4001,"Groundnut"),"n/a") -> 1.2214124 | D11: =IFERROR(AVERAGEIFS(Cleaned_Data!$T$2:$T$4001,Cleaned_Data!$E$2:$E$4001,"Zaid",Cleaned_Data!$D$2:$D$4001,"Groundnut"),"n/a") -> 1.0377778
A12: Chilli | B12: =IFERROR(AVERAGEIFS(Cleaned_Data!$T$2:$T$4001,Cleaned_Data!$E$2:$E$4001,"Kharif",Cleaned_Data!$D$2:$D$4001,"Chilli"),"n/a") -> 1.7314054 | C12: =IFERROR(AVERAGEIFS(Cleaned_Data!$T$2:$T$4001,Cleaned_Data!$E$2:$E$4001,"Rabi",Cleaned_Data!$D$2:$D$4001,"Chilli"),"n/a") -> 1.4615951 | D12: =IFERROR(AVERAGEIFS(Cleaned_Data!$T$2:$T$4001,Cleaned_Data!$E$2:$E$4001,"Zaid",Cleaned_Data!$D$2:$D$4001,"Chilli"),"n/a") -> 1.1778125
A13: Sugarcane | B13: =IFERROR(AVERAGEIFS(Cleaned_Data!$T$2:$T$4001,Cleaned_Data!$E$2:$E$4001,"Kharif",Cleaned_Data!$D$2:$D$4001,"Sugarcane"),"n/a") -> 53.45912 | C13: =IFERROR(AVERAGEIFS(Cleaned_Data!$T$2:$T$4001,Cleaned_Data!$E$2:$E$4001,"Rabi",Cleaned_Data!$D$2:$D$4001,"Sugarcane"),"n/a") -> 43.940388 | D13: =IFERROR(AVERAGEIFS(Cleaned_Data!$T$2:$T$4001,Cleaned_Data!$E$2:$E$4001,"Zaid",Cleaned_Data!$D$2:$D$4001,"Sugarcane"),"n/a") -> 38.423922
A16: Avg Profit per Farm (INR)
A17: Crop | B17: Kharif | C17: Rabi | D17: Zaid
A18: Wheat | B18: =IFERROR(AVERAGEIFS(Cleaned_Data!$Y$2:$Y$4001,Cleaned_Data!$E$2:$E$4001,"Kharif",Cleaned_Data!$D$2:$D$4001,"Wheat"),"n/a") -> -105871.87 | C18: =IFERROR(AVERAGEIFS(Cleaned_Data!$Y$2:$Y$4001,Cleaned_Data!$E$2:$E$4001,"Rabi",Cleaned_Data!$D$2:$D$4001,"Wheat"),"n/a") -> -119954.57 | D18: =IFERROR(AVERAGEIFS(Cleaned_Data!$Y$2:$Y$4001,Cleaned_Data!$E$2:$E$4001,"Zaid",Cleaned_Data!$D$2:$D$4001,"Wheat"),"n/a") -> -193208.95
A19: Rice | B19: =IFERROR(AVERAGEIFS(Cleaned_Data!$Y$2:$Y$4001,Cleaned_Data!$E$2:$E$4001,"Kharif",Cleaned_Data!$D$2:$D$4001,"Rice"),"n/a") -> -64903.404 | C19: =IFERROR(AVERAGEIFS(Cleaned_Data!$Y$2:$Y$4001,Cleaned_Data!$E$2:$E$4001,"Rabi",Cleaned_Data!$D$2:$D$4001,"Rice"),"n/a") -> -98427.869 | D19: =IFERROR(AVERAGEIFS(Cleaned_Data!$Y$2:$Y$4001,Cleaned_Data!$E$2:$E$4001,"Zaid",Cleaned_Data!$D$2:$D$4001,"Rice"),"n/a") -> -227239.34
A20: Maize | B20: =IFERROR(AVERAGEIFS(Cleaned_Data!$Y$2:$Y$4001,Cleaned_Data!$E$2:$E$4001,"Kharif",Cleaned_Data!$D$2:$D$4001,"Maize"),"n/a") -> -39332.671 | C20: =IFERROR(AVERAGEIFS(Cleaned_Data!$Y$2:$Y$4001,Cleaned_Data!$E$2:$E$4001,"Rabi",Cleaned_Data!$D$2:$D$4001,"Maize"),"n/a") -> -89133.403 | D20: =IFERROR(AVERAGEIFS(Cleaned_Data!$Y$2:$Y$4001,Cleaned_Data!$E$2:$E$4001,"Zaid",Cleaned_Data!$D$2:$D$4001,"Maize"),"n/a") -> -194049.17
A21: Cotton | B21: =IFERROR(AVERAGEIFS(Cleaned_Data!$Y$2:$Y$4001,Cleaned_Data!$E$2:$E$4001,"Kharif",Cleaned_Data!$D$2:$D$4001,"Cotton"),"n/a") -> 216999.55 | C21: =IFERROR(AVERAGEIFS(Cleaned_Data!$Y$2:$Y$4001,Cleaned_Data!$E$2:$E$4001,"Rabi",Cleaned_Data!$D$2:$D$4001,"Cotton"),"n/a") -> 107343.59 | D21: =IFERROR(AVERAGEIFS(Cleaned_Data!$Y$2:$Y$4001,Cleaned_Data!$E$2:$E$4001,"Zaid",Cleaned_Data!$D$2:$D$4001,"Cotton"),"n/a") -> -53925.337
A22: Pulses | B22: =IFERROR(AVERAGEIFS(Cleaned_Data!$Y$2:$Y$4001,Cleaned_Data!$E$2:$E$4001,"Kharif",Cleaned_Data!$D$2:$D$4001,"Pulses"),"n/a") -> 43338.896 | C22: =IFERROR(AVERAGEIFS(Cleaned_Data!$Y$2:$Y$4001,Cleaned_Data!$E$2:$E$4001,"Rabi",Cleaned_Data!$D$2:$D$4001,"Pulses"),"n/a") -> -14309.136 | D22: =IFERROR(AVERAGEIFS(Cleaned_Data!$Y$2:$Y$4001,Cleaned_Data!$E$2:$E$4001,"Zaid",Cleaned_Data!$D$2:$D$4001,"Pulses"),"n/a") -> -139227.81
A23: Groundnut | B23: =IFERROR(AVERAGEIFS(Cleaned_Data!$Y$2:$Y$4001,Cleaned_Data!$E$2:$E$4001,"Kharif",Cleaned_Data!$D$2:$D$4001,"Groundnut"),"n/a") -> 108265.44 | C23: =IFERROR(AVERAGEIFS(Cleaned_Data!$Y$2:$Y$4001,Cleaned_Data!$E$2:$E$4001,"Rabi",Cleaned_Data!$D$2:$D$4001,"Groundnut"),"n/a") -> 10416.542 | D23: =IFERROR(AVERAGEIFS(Cleaned_Data!$Y$2:$Y$4001,Cleaned_Data!$E$2:$E$4001,"Zaid",Cleaned_Data!$D$2:$D$4001,"Groundnut"),"n/a") -> -68872.5
A24: Chilli | B24: =IFERROR(AVERAGEIFS(Cleaned_Data!$Y$2:$Y$4001,Cleaned_Data!$E$2:$E$4001,"Kharif",Cleaned_Data!$D$2:$D$4001,"Chilli"),"n/a") -> 954380.42 | C24: =IFERROR(AVERAGEIFS(Cleaned_Data!$Y$2:$Y$4001,Cleaned_Data!$E$2:$E$4001,"Rabi",Cleaned_Data!$D$2:$D$4001,"Chilli"),"n/a") -> 638572.5 | D24: =IFERROR(AVERAGEIFS(Cleaned_Data!$Y$2:$Y$4001,Cleaned_Data!$E$2:$E$4001,"Zaid",Cleaned_Data!$D$2:$D$4001,"Chilli"),"n/a") -> 448659.09
A25: Sugarcane | B25: =IFERROR(AVERAGEIFS(Cleaned_Data!$Y$2:$Y$4001,Cleaned_Data!$E$2:$E$4001,"Kharif",Cleaned_Data!$D$2:$D$4001,"Sugarcane"),"n/a") -> 1000790.8 | C25: =IFERROR(AVERAGEIFS(Cleaned_Data!$Y$2:$Y$4001,Cleaned_Data!$E$2:$E$4001,"Rabi",Cleaned_Data!$D$2:$D$4001,"Sugarcane"),"n/a") -> 731612.86 | D25: =IFERROR(AVERAGEIFS(Cleaned_Data!$Y$2:$Y$4001,Cleaned_Data!$E$2:$E$4001,"Zaid",Cleaned_Data!$D$2:$D$4001,"Sugarcane"),"n/a") -> 583635.8

Sheet Season_State_Matrix
A1: Average Yield by Season x State
A2: Checks whether seasonal yield patterns are consistent across regions
A4: State | B4: Kharif | C4: Rabi | D4: Zaid
A5: Andhra Pradesh | B5: =IFERROR(AVERAGEIFS(Cleaned_Data!$T$2:$T$4001,Cleaned_Data!$E$2:$E$4001,"Kharif",Cleaned_Data!$B$2:$B$4001,"Andhra Pradesh"),"n/a") -> 5.681 | C5: =IFERROR(AVERAGEIFS(Cleaned_Data!$T$2:$T$4001,Cleaned_Data!$E$2:$E$4001,"Rabi",Cleaned_Data!$B$2:$B$4001,"Andhra Pradesh"),"n/a") -> 3.4670098 | D5: =IFERROR(AVERAGEIFS(Cleaned_Data!$T$2:$T$4001,Cleaned_Data!$E$2:$E$4001,"Zaid",Cleaned_Data!$B$2:$B$4001,"Andhra Pradesh"),"n/a") -> 4.4414118
A6: Telangana | B6: =IFERROR(AVERAGEIFS(Cleaned_Data!$T$2:$T$4001,Cleaned_Data!$E$2:$E$4001,"Kharif",Cleaned_Data!$B$2:$B$4001,"Telangana"),"n/a") -> 5.5516667 | C6: =IFERROR(AVERAGEIFS(Cleaned_Data!$T$2:$T$4001,Cleaned_Data!$E$2:$E$4001,"Rabi",Cleaned_Data!$B$2:$B$4001,"Telangana"),"n/a") -> 4.7963959 | D6: =IFERROR(AVERAGEIFS(Cleaned_Data!$T$2:$T$4001,Cleaned_Data!$E$2:$E$4001,"Zaid",Cleaned_Data!$B$2:$B$4001,"Telangana"),"n/a") -> 4.2418824
A7: Maharashtra | B7: =IFERROR(AVERAGEIFS(Cleaned_Data!$T$2:$T$4001,Cleaned_Data!$E$2:$E$4001,"Kharif",Cleaned_Data!$B$2:$B$4001,"Maharashtra"),"n/a") -> 5.4326577 | C7: =IFERROR(AVERAGEIFS(Cleaned_Data!$T$2:$T$4001,Cleaned_Data!$E$2:$E$4001,"Rabi",Cleaned_Data!$B$2:$B$4001,"Maharashtra"),"n/a") -> 5.5019266 | D7: =IFERROR(AVERAGEIFS(Cleaned_Data!$T$2:$T$4001,Cleaned_Data!$E$2:$E$4001,"Zaid",Cleaned_Data!$B$2:$B$4001,"Maharashtra"),"n/a") -> 2.2668056
A8: Madhya Pradesh | B8: =IFERROR(AVERAGEIFS(Cleaned_Data!$T$2:$T$4001,Cleaned_Data!$E$2:$E$4001,"Kharif",Cleaned_Data!$B$2:$B$4001,"Madhya Pradesh"),"n/a") -> 5.9895575 | C8: =IFERROR(AVERAGEIFS(Cleaned_Data!$T$2:$T$4001,Cleaned_Data!$E$2:$E$4001,"Rabi",Cleaned_Data!$B$2:$B$4001,"Madhya Pradesh"),"n/a") -> 3.7607692 | D8: =IFERROR(AVERAGEIFS(Cleaned_Data!$T$2:$T$4001,Cleaned_Data!$E$2:$E$4001,"Zaid",Cleaned_Data!$B$2:$B$4001,"Madhya Pradesh"),"n/a") -> 5.4615873
A9: Karnataka | B9: =IFERROR(AVERAGEIFS(Cleaned_Data!$T$2:$T$4001,Cleaned_Data!$E$2:$E$4001,"Kharif",Cleaned_Data!$B$2:$B$4001,"Karnataka"),"n/a") -> 6.4566507 | C9: =IFERROR(AVERAGEIFS(Cleaned_Data!$T$2:$T$4001,Cleaned_Data!$E$2:$E$4001,"Rabi",Cleaned_Data!$B$2:$B$4001,"Karnataka"),"n/a") -> 4.7730583 | D9: =IFERROR(AVERAGEIFS(Cleaned_Data!$T$2:$T$4001,Cleaned_Data!$E$2:$E$4001,"Zaid",Cleaned_Data!$B$2:$B$4001,"Karnataka"),"n/a") -> 6.6232432
A10: Gujarat | B10: =IFERROR(AVERAGEIFS(Cleaned_Data!$T$2:$T$4001,Cleaned_Data!$E$2:$E$4001,"Kharif",Cleaned_Data!$B$2:$B$4001,"Gujarat"),"n/a") -> 6.3384163 | C10: =IFERROR(AVERAGEIFS(Cleaned_Data!$T$2:$T$4001,Cleaned_Data!$E$2:$E$4001,"Rabi",Cleaned_Data!$B$2:$B$4001,"Gujarat"),"n/a") -> 5.65725 | D10: =IFERROR(AVERAGEIFS(Cleaned_Data!$T$2:$T$4001,Cleaned_Data!$E$2:$E$4001,"Zaid",Cleaned_Data!$B$2:$B$4001,"Gujarat"),"n/a") -> 4.0750746
A11: Tamil Nadu | B11: =IFERROR(AVERAGEIFS(Cleaned_Data!$T$2:$T$4001,Cleaned_Data!$E$2:$E$4001,"Kharif",Cleaned_Data!$B$2:$B$4001,"Tamil Nadu"),"n/a") -> 5.520534 | C11: =IFERROR(AVERAGEIFS(Cleaned_Data!$T$2:$T$4001,Cleaned_Data!$E$2:$E$4001,"Rabi",Cleaned_Data!$B$2:$B$4001,"Tamil Nadu"),"n/a") -> 4.4950481 | D11: =IFERROR(AVERAGEIFS(Cleaned_Data!$T$2:$T$4001,Cleaned_Data!$E$2:$E$4001,"Zaid",Cleaned_Data!$B$2:$B$4001,"Tamil Nadu"),"n/a") -> 4.0977465
A12: Punjab | B12: =IFERROR(AVERAGEIFS(Cleaned_Data!$T$2:$T$4001,Cleaned_Data!$E$2:$E$4001,"Kharif",Cleaned_Data!$B$2:$B$4001,"Punjab"),"n/a") -> 4.1006335 | C12: =IFERROR(AVERAGEIFS(Cleaned_Data!$T$2:$T$4001,Cleaned_Data!$E$2:$E$4001,"Rabi",Cleaned_Data!$B$2:$B$4001,"Punjab"),"n/a") -> 8.6093548 | D12: =IFERROR(AVERAGEIFS(Cleaned_Data!$T$2:$T$4001,Cleaned_Data!$E$2:$E$4001,"Zaid",Cleaned_Data!$B$2:$B$4001,"Punjab"),"n/a") -> 5.9096104

Sheet Irrigation_Analysis
A1: Irrigation Method Usage & Efficiency by Season
A4: Farm Count
A5: Irrigation Method | B5: Kharif | C5: Rabi | D5: Zaid | F5: Total
A6: Drip | B6: =COUNTIFS(Cleaned_Data!$E$2:$E$4001,"Kharif",Cleaned_Data!$P$2:$P$4001,"Drip") -> 405 | C6: =COUNTIFS(Cleaned_Data!$E$2:$E$4001,"Rabi",Cleaned_Data!$P$2:$P$4001,"Drip") -> 370 | D6: =COUNTIFS(Cleaned_Data!$E$2:$E$4001,"Zaid",Cleaned_Data!$P$2:$P$4001,"Drip") -> 140 | F6: =SUM(B6:D6) -> 915
A7: Flood | B7: =COUNTIFS(Cleaned_Data!$E$2:$E$4001,"Kharif",Cleaned_Data!$P$2:$P$4001,"Flood") -> 590 | C7: =COUNTIFS(Cleaned_Data!$E$2:$E$4001,"Rabi",Cleaned_Data!$P$2:$P$4001,"Flood") -> 526 | D7: =COUNTIFS(Cleaned_Data!$E$2:$E$4001,"Zaid",Cleaned_Data!$P$2:$P$4001,"Flood") -> 194 | F7: =SUM(B7:D7) -> 1310
A8: Rainfed | B8: =COUNTIFS(Cleaned_Data!$E$2:$E$4001,"Kharif",Cleaned_Data!$P$2:$P$4001,"Rainfed") -> 463 | C8: =COUNTIFS(Cleaned_Data!$E$2:$E$4001,"Rabi",Cleaned_Data!$P$2:$P$4001,"Rainfed") -> 438 | D8: =COUNTIFS(Cleaned_Data!$E$2:$E$4001,"Zaid",Cleaned_Data!$P$2:$P$4001,"Rainfed") -> 140 | F8: =SUM(B8:D8) -> 1041
A9: Sprinkler | B9: =COUNTIFS(Cleaned_Data!$E$2:$E$4001,"Kharif",Cleaned_Data!$P$2:$P$4001,"Sprinkler") -> 321 | C9: =COUNTIFS(Cleaned_Data!$E$2:$E$4001,"Rabi",Cleaned_Data!$P$2:$P$4001,"Sprinkler") -> 293 | D9: =COUNTIFS(Cleaned_Data!$E$2:$E$4001,"Zaid",Cleaned_Data!$P$2:$P$4001,"Sprinkler") -> 120 | F9: =SUM(B9:D9) -> 734
A12: Avg Water Efficiency (t/1000m3)
A13: Irrigation Method | B13: Kharif | C13: Rabi | D13: Zaid
A14: Drip | B14: =IFERROR(AVERAGEIFS(Cleaned_Data!$AA$2:$AA$4001,Cleaned_Data!$E$2:$E$4001,"Kharif",Cleaned_Data!$P$2:$P$4001,"Drip"),"n/a") -> 6.8038173 | C14: =IFERROR(AVERAGEIFS(Cleaned_Data!$AA$2:$AA$4001,Cleaned_Data!$E$2:$E$4001,"Rabi",Cleaned_Data!$P$2:$P$4001,"Drip"),"n/a") -> 6.0471568 | D14: =IFERROR(AVERAGEIFS(Cleaned_Data!$AA$2:$AA$4001,Cleaned_Data!$E$2:$E$4001,"Zaid",Cleaned_Data!$P$2:$P$4001,"Drip"),"n/a") -> 5.2959214
